Workbook

Sheet Best Outcomes
A1: SKU | B1: Recommendation | C1: Candidate Type | D1: Current Price | E1: Winning Scenario | F1: Evaluation Score | G1: Adjusted Price | H1: Adjusted Difference $ | I1: Adjusted Difference % | J1: Adjusted Gross Revenue | K1: Gross Revenue Impact $ | L1: Gross Revenue Lift % | M1: Adjusted Gross Profit | N1: Gross Profit Impact $ | O1: Gross Profit Lift % | P1: Gross Profit Margin % | Q1: Gross Profit Margin Lift % | R1: LTV Protected | S1: LTV Sacrificed | T1: LTV Protection-Risk Ratio
A2: {=INDEX(Model_Input[SKU], ROW()-1)} -> SKU-1000 | B2: {=INDEX(Engine!$F$2:$F$2201, Helpers!$B7)} -> Raise | C2: {=INDEX(Engine!$G$2:$G$2201, Helpers!$B7)} -> Full | D2: {=INDEX(Engine!$H$2:$H$2201, Helpers!$B7)} -> 76.53 | E2: =IF(Helpers!$F7 >= 0.05, "Reprice", "Hold") -> Reprice | F2: =Helpers!$C7 -> 0.12635537 | G2: =IF($E2="Hold", $D2, Helpers!$D7) -> 78.975794 | H2: =$G2-$D2 -> 2.4457937 | I2: =IFERROR($H2/$D2, 0) -> 0.031958627 | J2: {=IF($E2="Hold", INDEX(Engine!$K$2:$K$2201, Helpers!$B7), INDEX(Engine!$X$2:$X$2201, Helpers!$B7))} -> 1871.1891 | K2: {=$J2 - INDEX(Engine!$K$2:$K$2201, Helpers!$B7)} -> 34.469053 | L2: =IF($E2="Hold", 0, Helpers!$E7) -> 0.018766635 | M2: {=IF($E2="Hold", INDEX(Engine!$L$2:$L$2201, Helpers!$B7), INDEX(Engine!$Y$2:$Y$2201, Helpers!$B7))} -> 616.39733 | N2: {=$M2 - INDEX(Engine!$L$2:$L$2201, Helpers!$B7)} -> 50.71733 | O2: =IF($E2="Hold", 0, Helpers!$F7) -> 0.08965728 | P2: =IFERROR($M2/$J2, 0) -> 0.32941478 | Q2: {=$P2 - INDEX(Engine!$M$2:$M$2201, Helpers!$B7)} -> 0.021430983 | R2: {=IF($E2="Hold", INDEX(Engine!$R$2:$R$2201, Helpers!$B7), INDEX(Engine!$AF$2:$AF$2201, Helpers!$B7))} -> 358.09401 | S2: {=INDEX(Engine!$R$2:$R$2201, Helpers!$B7) - $R2} -> 537.14101 | T2: =IFERROR($R2/$S2, 0) -> 0.66666667
A3: {=INDEX(Model_Input[SKU], ROW()-1)} -> SKU-1001 | B3: {=INDEX(Engine!$F$2:$F$2201, Helpers!$B8)} -> Raise | C3: {=INDEX(Engine!$G$2:$G$2201, Helpers!$B8)} -> Full | D3: {=INDEX(Engine!$H$2:$H$2201, Helpers!$B8)} -> 53.26 | E3: =IF(Helpers!$F8 >= 0.05, "Reprice", "Hold") -> Reprice | F3: =Helpers!$C8 -> 0.18771631 | G3: =IF($E3="Hold", $D3, Helpers!$D8) -> 55.842395 | H3: =$G3-$D3 -> 2.5823951 | I3: =IFERROR($H3/$D3, 0) -> 0.048486577 | J3: {=IF($E3="Hold", INDEX(Engine!$K$2:$K$2201, Helpers!$B8), INDEX(Engine!$X$2:$X$2201, Helpers!$B8))} -> 1149.9464 | K3: {=$J3 - INDEX(Engine!$K$2:$K$2201, Helpers!$B8)} -> 31.486401 | L3: =IF($E3="Hold", 0, Helpers!$E8) -> 0.028151567 | M3: {=IF($E3="Hold", INDEX(Engine!$L$2:$L$2201, Helpers!$B8), INDEX(Engine!$Y$2:$Y$2201, Helpers!$B8))} -> 395.42941 | N3: {=$M3 - INDEX(Engine!$L$2:$L$2201, Helpers!$B8)} -> 46.409406 | O3: =IF($E3="Hold", 0, Helpers!$F8) -> 0.13297062 | P3: =IFERROR($M3/$J3, 0) -> 0.34386768 | Q3: {=$P3 - INDEX(Engine!$M$2:$M$2201, Helpers!$B8)} -> 0.03181361 | R3: {=IF($E3="Hold", INDEX(Engine!$R$2:$R$2201, Helpers!$B8), INDEX(Engine!$AF$2:$AF$2201, Helpers!$B8))} -> 449.41351 | S3: {=INDEX(Engine!$R$2:$R$2201, Helpers!$B8) - $R3} -> 674.12027 | T3: =IFERROR($R3/$S3, 0) -> 0.66666667
A4: {=INDEX(Model_Input[SKU], ROW()-1)} -> SKU-1004 | B4: {=INDEX(Engine!$F$2:$F$2201, Helpers!$B9)} -> Hold | C4: {=INDEX(Engine!$G$2:$G$2201, Helpers!$B9)} -> Full | D4: {=INDEX(Engine!$H$2:$H$2201, Helpers!$B9)} -> 18.39 | E4: =IF(Helpers!$F9 >= 0.05, "Reprice", "Hold") -> Reprice | F4: =Helpers!$C9 -> 0.14008396 | G4: =IF($E4="Hold", $D4, Helpers!$D9) -> 19.551373 | H4: =$G4-$D4 -> 1.161373 | I4: =IFERROR($H4/$D4, 0) -> 0.063152419 | J4: {=IF($E4="Hold", INDEX(Engine!$K$2:$K$2201, Helpers!$B9), INDEX(Engine!$X$2:$X$2201, Helpers!$B9))} -> 323.97727 | K4: {=$J4 - INDEX(Engine!$K$2:$K$2201, Helpers!$B9)} -> 11.347269 | L4: =IF($E4="Hold", 0, Helpers!$E9) -> 0.03629616 | M4: {=IF($E4="Hold", INDEX(Engine!$L$2:$L$2201, Helpers!$B9), INDEX(Engine!$Y$2:$Y$2201, Helpers!$B9))} -> 187.10441 | N4: {=$M4 - INDEX(Engine!$L$2:$L$2201, Helpers!$B9)} -> 14.894414 | O4: =IF($E4="Hold", 0, Helpers!$F9) -> 0.086489831 | P4: =IFERROR($M4/$J4, 0) -> 0.57752328 | Q4: {=$P4 - INDEX(Engine!$M$2:$M$2201, Helpers!$B9)} -> 0.026680427 | R4: {=IF($E4="Hold", INDEX(Engine!$R$2:$R$2201, Helpers!$B9), INDEX(Engine!$AF$2:$AF$2201, Helpers!$B9))} -> 375.63072 | S4: {=INDEX(Engine!$R$2:$R$2201, Helpers!$B9) - $R4} -> 563.44608 | T4: =IFERROR($R4/$S4, 0) -> 0.66666667
A5: {=INDEX(Model_Input[SKU], ROW()-1)} -> SKU-1005 | B5: {=INDEX(Engine!$F$2:$F$2201, Helpers!$B10)} -> Raise | C5: {=INDEX(Engine!$G$2:$G$2201, Helpers!$B10)} -> Full | D5: {=INDEX(Engine!$H$2:$H$2201, Helpers!$B10)} -> 29.62 | E5: =IF(Helpers!$F10 >= 0.05, "Reprice", "Hold") -> Hold | F5: =Helpers!$C10 -> 0 | G5: =IF($E5="Hold", $D5, Helpers!$D10) -> 29.62 | H5: =$G5-$D5 -> 0 | I5: =IFERROR($H5/$D5, 0) -> 0 | J5: {=IF($E5="Hold", INDEX(Engine!$K$2:$K$2201, Helpers!$B10), INDEX(Engine!$X$2:$X$2201, Helpers!$B10))} -> 1362.52 | K5: {=$J5 - INDEX(Engine!$K$2:$K$2201, Helpers!$B10)} -> 0 | L5: =IF($E5="Hold", 0, Helpers!$E10) -> 0 | M5: {=IF($E5="Hold", INDEX(Engine!$L$2:$L$2201, Helpers!$B10), INDEX(Engine!$Y$2:$Y$2201, Helpers!$B10))} -> 469.2 | N5: {=$M5 - INDEX(Engine!$L$2:$L$2201, Helpers!$B10)} -> 0 | O5: =IF($E5="Hold", 0, Helpers!$F10) -> 0 | P5: =IFERROR($M5/$J5, 0) -> 0.34436192 | Q5: {=$P5 - INDEX(Engine!$M$2:$M$2201, Helpers!$B10)} -> 0 | R5: {=IF($E5="Hold", INDEX(Engine!$R$2:$R$2201, Helpers!$B10), INDEX(Engine!$AF$2:$AF$2201, Helpers!$B10))} -> 927.1195 | S5: {=INDEX(Engine!$R$2:$R$2201, Helpers!$B10) - $R5} -> 0 | T5: =IFERROR($R5/$S5, 0) -> 0
A6: {=INDEX(Model_Input[SKU], ROW()-1)} -> SKU-1006 | B6: {=INDEX(Engine!$F$2:$F$2201, Helpers!$B11)} -> Hold | C6: {=INDEX(Engine!$G$2:$G$2201, Helpers!$B11)} -> Full | D6: {=INDEX(Engine!$H$2:$H$2201, Helpers!$B11)} -> 113.18 | E6: =IF(Helpers!$F11 >= 0.05, "Reprice", "Hold") -> Reprice | F6: =Helpers!$C11 -> 0.089473506 | G6: =IF($E6="Hold", $D6, Helpers!$D11) -> 118.51611 | H6: =$G6-$D6 -> 5.3361073 | I6: =IFERROR($H6/$D6, 0) -> 0.047147087 | J6: {=IF($E6="Hold", INDEX(Engine!$K$2:$K$2201, Helpers!$B11), INDEX(Engine!$X$2:$X$2201, Helpers!$B11))} -> 2790.7448 | K6: {=$J6 - INDEX(Engine!$K$2:$K$2201, Helpers!$B11)} -> 74.424759 | L6: =IF($E6="Hold", 0, Helpers!$E11) -> 0.027399113 | M6: {=IF($E6="Hold", INDEX(Engine!$L$2:$L$2201, Helpers!$B11), INDEX(Engine!$Y$2:$Y$2201, Helpers!$B11))} -> 1872.1612 | N6: {=$M6 - INDEX(Engine!$L$2:$L$2201, Helpers!$B11)} -> 92.081155 | O6: =IF($E6="Hold", 0, Helpers!$F11) -> 0.051728661 | P6: =IFERROR($M6/$J6, 0) -> 0.67084643 | Q6: {=$P6 - INDEX(Engine!$M$2:$M$2201, Helpers!$B11)} -> 0.015518632 | R6: {=IF($E6="Hold", INDEX(Engine!$R$2:$R$2201, Helpers!$B11), INDEX(Engine!$AF$2:$AF$2201, Helpers!$B11))} -> 396.9034 | S6: {=INDEX(Engine!$R$2:$R$2201, Helpers!$B11) - $R6} -> 595.3551 | T6: =IFERROR($R6/$S6, 0) -> 0.66666667
A7: {=INDEX(Model_Input[SKU], ROW()-1)} -> SKU-1009 | B7: {=INDEX(Engine!$F$2:$F$2201, Helpers!$B12)} -> Raise | C7: {=INDEX(Engine!$G$2:$G$2201, Helpers!$B12)} -> Full | D7: {=INDEX(Engine!$H$2:$H$2201, Helpers!$B12)} -> 177.91 | E7: =IF(Helpers!$F12 >= 0.05, "Reprice", "Hold") -> Reprice | F7: =Helpers!$C12 -> 0.22231295 | G7: =IF($E7="Hold", $D7, Helpers!$D12) -> 197.38145 | H7: =$G7-$D7 -> 19.471452 | I7: =IFERROR($H7/$D7, 0) -> 0.10944552 | J7: {=IF($E7="Hold", INDEX(Engine!$K$2:$K$2201, Helpers!$B12), INDEX(Engine!$X$2:$X$2201, Helpers!$B12))} -> 6794.6561 | K7: {=$J7 - INDEX(Engine!$K$2:$K$2201, Helpers!$B12)} -> 389.89606 | L7: =IF($E7="Hold", 0, Helpers!$E12) -> 0.060875983 | M7: {=IF($E7="Hold", INDEX(Engine!$L$2:$L$2201, Helpers!$B12), INDEX(Engine!$Y$2:$Y$2201, Helpers!$B12))} -> 4264.8374 | N7: {=$M7 - INDEX(Engine!$L$2:$L$2201, Helpers!$B12)} -> 505.71744 | O7: =IF($E7="Hold", 0, Helpers!$F12) -> 0.1345308 | P7: =IFERROR($M7/$J7, 0) -> 0.62767525 | Q7: {=$P7 - INDEX(Engine!$M$2:$M$2201, Helpers!$B12)} -> 0.040749276 | R7: {=IF($E7="Hold", INDEX(Engine!$R$2:$R$2201, Helpers!$B12), INDEX(Engine!$AF$2:$AF$2201, Helpers!$B12))} -> 688.8869 | S7: {=INDEX(Engine!$R$2:$R$2201, Helpers!$B12) - $R7} -> 1033.3304 | T7: =IFERROR($R7/$S7, 0) -> 0.66666667
A8: {=INDEX(Model_Input[SKU], ROW()-1)} -> SKU-1010 | B8: {=INDEX(Engine!$F$2:$F$2201, Helpers!$B13)} -> Raise | C8: {=INDEX(Engine!$G$2:$G$2201, Helpers!$B13)} -> Full | D8: {=INDEX(Engine!$H$2:$H$2201, Helpers!$B13)} -> 45.86 | E8: =IF(Helpers!$F13 >= 0.05, "Reprice", "Hold") -> Reprice | F8: =Helpers!$C13 -> 0.38670957 | G8: =IF($E8="Hold", $D8, Helpers!$D13) -> 52.899021 | H8: =$G8-$D8 -> 7.0390209 | I8: =IFERROR($H8/$D8, 0) -> 0.15348934 | J8: {=IF($E8="Hold", INDEX(Engine!$K$2:$K$2201, Helpers!$B13), INDEX(Engine!$X$2:$X$2201, Helpers!$B13))} -> 2085.3524 | K8: {=$J8 - INDEX(Engine!$K$2:$K$2201, Helpers!$B13)} -> 159.23236 | L8: =IF($E8="Hold", 0, Helpers!$E13) -> 0.082670011 | M8: {=IF($E8="Hold", INDEX(Engine!$L$2:$L$2201, Helpers!$B13), INDEX(Engine!$Y$2:$Y$2201, Helpers!$B13))} -> 1104.9427 | N8: {=$M8 - INDEX(Engine!$L$2:$L$2201, Helpers!$B13)} -> 223.36266 | O8: =IF($E8="Hold", 0, Helpers!$F13) -> 0.2533663 | P8: =IFERROR($M8/$J8, 0) -> 0.52985897 | Q8: {=$P8 - INDEX(Engine!$M$2:$M$2201, Helpers!$B13)} -> 0.072161634 | R8: {=IF($E8="Hold", INDEX(Engine!$R$2:$R$2201, Helpers!$B13), INDEX(Engine!$AF$2:$AF$2201, Helpers!$B13))} -> 666.16547 | S8: {=INDEX(Engine!$R$2:$R$2201, Helpers!$B13) - $R8} -> 999.2482 | T8: =IFERROR($R8/$S8, 0) -> 0.66666667
A9: {=INDEX(Model_Input[SKU], ROW()-1)} -> SKU-1011 | B9: {=INDEX(Engine!$F$2:$F$2201, Helpers!$B14)} -> Raise | C9: {=INDEX(Engine!$G$2:$G$2201, Helpers!$B14)} -> Full | D9: {=INDEX(Engine!$H$2:$H$2201, Helpers!$B14)} -> 67.56 | E9: =IF(Helpers!$F14 >= 0.05, "Reprice", "Hold") -> Reprice | F9: =Helpers!$C14 -> 0.21602349 | G9: =IF($E9="Hold", $D9, Helpers!$D14) -> 71.933095 | H9: =$G9-$D9 -> 4.3730955 | I9: =IFERROR($H9/$D9, 0) -> 0.064729063 | J9: {=IF($E9="Hold", INDEX(Engine!$K$2:$K$2201, Helpers!$B14), INDEX(Engine!$X$2:$X$2201, Helpers!$B14))} -> 1541.5539 | K9: {=$J9 - INDEX(Engine!$K$2:$K$2201, Helpers!$B14)} -> 55.233876 | L9: =IF($E9="Hold", 0, Helpers!$E14) -> 0.037161497 | M9: {=IF($E9="Hold", INDEX(Engine!$L$2:$L$2201, Helpers!$B14), INDEX(Engine!$Y$2:$Y$2201, Helpers!$B14))} -> 615.54697 | N9: {=$M9 - INDEX(Engine!$L$2:$L$2201, Helpers!$B14)} -> 79.846973 | O9: =IF($E9="Hold", 0, Helpers!$F14) -> 0.14905166 | P9: =IFERROR($M9/$J9, 0) -> 0.39930293 | Q9: {=$P9 - INDEX(Engine!$M$2:$M$2201, Helpers!$B14)} -> 0.038882559 | R9: {=IF($E9="Hold", INDEX(Engine!$R$2:$R$2201, Helpers!$B14), INDEX(Engine!$AF$2:$AF$2201, Helpers!$B14))} -> 429.27827 | S9: {=INDEX(Engine!$R$2:$R$2201, Helpers!$B14) - $R9} -> 643.91741 | T9: =IFERROR($R9/$S9, 0) -> 0.66666667
A10: {=INDEX(Model_Input[SKU], ROW()-1)} -> SKU-1012 | B10: {=INDEX(Engine!$F$2:$F$2201, Helpers!$B15)} -> Raise | C10: {=INDEX(Engine!$G$2:$G$2201, Helpers!$B15)} -> Full | D10: {=INDEX(Engine!$H$2:$H$2201, Helpers!$B15)} -> 20.37 | E10: =IF(Helpers!$F15 >= 0.05, "Reprice", "Hold") -> Hold | F10: =Helpers!$C15 -> 0 | G10: =IF($E10="Hold", $D10, Helpers!$D15) -> 20.37 | H10: =$G10-$D10 -> 0 | I10: =IFERROR($H10/$D10, 0) -> 0 | J10: {=IF($E10="Hold", INDEX(Engine!$K$2:$K$2201, Helpers!$B15), INDEX(Engine!$X$2:$X$2201, Helpers!$B15))} -> 305.55 | K10: {=$J10 - INDEX(Engine!$K$2:$K$2201, Helpers!$B15)} -> 0 | L10: =IF($E10="Hold", 0, Helpers!$E15) -> 0 | M10: {=IF($E10="Hold", INDEX(Engine!$L$2:$L$2201, Helpers!$B15), INDEX(Engine!$Y$2:$Y$2201, Helpers!$B15))} -> 159.15 | N10: {=$M10 - INDEX(Engine!$L$2:$L$2201, Helpers!$B15)} -> 0 | O10: =IF($E10="Hold", 0, Helpers!$F15) -> 0 | P10: =IFERROR($M10/$J10, 0) -> 0.52086402 | Q10: {=$P10 - INDEX(Engine!$M$2:$M$2201, Helpers!$B15)} -> 0 | R10: {=IF($E10="Hold", INDEX(Engine!$R$2:$R$2201, Helpers!$B15), INDEX(Engine!$AF$2:$AF$2201, Helpers!$B15))} -> 311.63259 | S10: {=INDEX(Engine!$R$2:$R$2201, Helpers!$B15) - $R10} -> 0 | T10: =IFERROR($R10/$S10, 0) -> 0
A11: {=INDEX(Model_Input[SKU], ROW()-1)} -> SKU-1013 | B11: {=INDEX(Engine!$F$2:$F$2201, Helpers!$B16)} -> Raise | C11: {=INDEX(Engine!$G$2:$G$2201, Helpers!$B16)} -> Constrained | D11: {=INDEX(Engine!$H$2:$H$2201, Helpers!$B16)} -> 84.95 | E11: =IF(Helpers!$F16 >= 0.05, "Reprice", "Hold") -> Hold | F11: =Helpers!$C16 -> 0 | G11: =IF($E11="Hold", $D11, Helpers!$D16) -> 84.95 | H11: =$G11-$D11 -> 0 | I11: =IFERROR($H11/$D11, 0) -> 0 | J11: {=IF($E11="Hold", INDEX(Engine!$K$2:$K$2201, Helpers!$B16), INDEX(Engine!$X$2:$X$2201, Helpers!$B16))} -> 3058.2 | K11: {=$J11 - INDEX(Engine!$K$2:$K$2201, Helpers!$B16)} -> 0 | L11: =IF($E11="Hold", 0, Helpers!$E16) -> 0 | M11: {=IF($E11="Hold", INDEX(Engine!$L$2:$L$2201, Helpers!$B16), INDEX(Engine!$Y$2:$Y$2201, Helpers!$B16))} -> 1147.68 | N11: {=$M11 - INDEX(Engine!$L$2:$L$2201, Helpers!$B16)} -> 0 | O11: =IF($E11="Hold", 0, Helpers!$F16) -> 0 | P11: =IFERROR($M11/$J11, 0) -> 0.37527958 | Q11: {=$P11 - INDEX(Engine!$M$2:$M$2201, Helpers!$B16)} -> 0 | R11: {=IF($E11="Hold", INDEX(Engine!$R$2:$R$2201, Helpers!$B16), INDEX(Engine!$AF$2:$AF$2201, Helpers!$B16))} -> 894.15433 | S11: {=INDEX(Engine!$R$2:$R$2201, Helpers!$B16) - $R11} -> 0 | T11: =IFERROR($R11/$S11, 0) -> 0
A12: {=INDEX(Model_Input[SKU], ROW()-1)} -> SKU-1014 | B12: {=INDEX(Engine!$F$2:$F$2201, Helpers!$B17)} -> Raise | C12: {=INDEX(Engine!$G$2:$G$2201, Helpers!$B17)} -> Full | D12: {=INDEX(Engine!$H$2:$H$2201, Helpers!$B17)} -> 143.8 | E12: =IF(Helpers!$F17 >= 0.05, "Reprice", "Hold") -> Reprice | F12: =Helpers!$C17 -> 0.27833494 | G12: =IF($E12="Hold", $D12, Helpers!$D17) -> 163.17672 | H12: =$G12-$D12 -> 19.376717 | I12: =IFERROR($H12/$D12, 0) -> 0.13474768 | J12: {=IF($E12="Hold", INDEX(Engine!$K$2:$K$2201, Helpers!$B17), INDEX(Engine!$X$2:$X$2201, Helpers!$B17))} -> 4477.0677 | K12: {=$J12 - INDEX(Engine!$K$2:$K$2201, Helpers!$B17)} -> 306.86765 | L12: =IF($E12="Hold", 0, Helpers!$E17) -> 0.073585836 | M12: {=IF($E12="Hold", INDEX(Engine!$L$2:$L$2201, Helpers!$B17), INDEX(Engine!$Y$2:$Y$2201, Helpers!$B17))} -> 2771.8626 | N12: {=$M12 - INDEX(Engine!$L$2:$L$2201, Helpers!$B17)} -> 404.01265 | O12: =IF($E12="Hold", 0, Helpers!$F17) -> 0.17062426 | P12: =IFERROR($M12/$J12, 0) -> 0.61912458 | Q12: {=$P12 - INDEX(Engine!$M$2:$M$2201, Helpers!$B17)} -> 0.051322081 | R12: {=IF($E12="Hold", INDEX(Engine!$R$2:$R$2201, Helpers!$B17), INDEX(Engine!$AF$2:$AF$2201, Helpers!$B17))} -> 422.51294 | S12: {=INDEX(Engine!$R$2:$R$2201, Helpers!$B17) - $R12} -> 633.76941 | T12: =IFERROR($R12/$S12, 0) -> 0.66666667
A13: {=INDEX(Model_Input[SKU], ROW()-1)} -> SKU-1017 | B13: {=INDEX(Engine!$F$2:$F$2201, Helpers!$B18)} -> Raise | C13: {=INDEX(Engine!$G$2:$G$2201, Helpers!$B18)} -> Full | D13: {=INDEX(Engine!$H$2:$H$2201, Helpers!$B18)} -> 63.19 | E13: =IF(Helpers!$F18 >= 0.05, "Reprice", "Hold") -> Hold | F13: =Helpers!$C18 -> 0.032641382 | G13: =IF($E13="Hold", $D13, Helpers!$D18) -> 63.19 | H13: =$G13-$D13 -> 0 | I13: =IFERROR($H13/$D13, 0) -> 0 | J13: {=IF($E13="Hold", INDEX(Engine!$K$2:$K$2201, Helpers!$B18), INDEX(Engine!$X$2:$X$2201, Helpers!$B18))} -> 1200.61 | K13: {=$J13 - INDEX(Engine!$K$2:$K$2201, Helpers!$B18)} -> 0 | L13: =IF($E13="Hold", 0, Helpers!$E18) -> 0 | M13: {=IF($E13="Hold", INDEX(Engine!$L$2:$L$2201, Helpers!$B18), INDEX(Engine!$Y$2:$Y$2201, Helpers!$B18))} -> 413.06 | N13: {=$M13 - INDEX(Engine!$L$2:$L$2201, Helpers!$B18)} -> 0 | O13: =IF($E13="Hold", 0, Helpers!$F18) -> 0 | P13: =IFERROR($M13/$J13, 0) -> 0.34404178 | Q13: {=$P13 - INDEX(Engine!$M$2:$M$2201, Helpers!$B18)} -> 0 | R13: {=IF($E13="Hold", INDEX(Engine!$R$2:$R$2201, Helpers!$B18), INDEX(Engine!$AF$2:$AF$2201, Helpers!$B18))} -> 858.15236 | S13: {=INDEX(Engine!$R$2:$R$2201, Helpers!$B18) - $R13} -> 0 | T13: =IFERROR($R13/$S13, 0) -> 0
... A43: {=INDEX(Model_Input[SKU], ROW()-1)} -> SKU-1049 | B43: {=INDEX(Engine!$F$2:$F$2201, Helpers!$B48)} -> Raise | C43: {=INDEX(Engine!$G$2:$G$2201, Helpers!$B48)} -> Full | D43: {=INDEX(Engine!$H$2:$H$2201, Helpers!$B48)} -> 99.75 | E43: =IF(Helpers!$F48 >= 0.05, "Reprice", "Hold") -> Reprice | F43: =Helpers!$C48 -> 0.12768917 | G43: =IF($E43="Hold", $D43, Helpers!$D48) -> 106.16045 | H43: =$G43-$D43 -> 6.4104547 | I43: =IFERROR($H43/$D43, 0) -> 0.06426521 | J43: {=IF($E43="Hold", INDEX(Engine!$K$2:$K$2201, Helpers!$B48), INDEX(Engine!$X$2:$X$2201, Helpers!$B48))} -> 3516.6705 | K43: {=$J43 - INDEX(Engine!$K$2:$K$2201, Helpers!$B48)} -> 125.1705 | L43: =IF($E43="Hold", 0, Helpers!$E48) -> 0.036907119 | M43: {=IF($E43="Hold", INDEX(Engine!$L$2:$L$2201, Helpers!$B48), INDEX(Engine!$Y$2:$Y$2201, Helpers!$B48))} -> 2253.5764 | N43: {=$M43 - INDEX(Engine!$L$2:$L$2201, Helpers!$B48)} -> 158.49638 | O43: =IF($E43="Hold", 0, Helpers!$F48) -> 0.075651706 | P43: =IFERROR($M43/$J43, 0) -> 0.64082671 | Q43: {=$P43 - INDEX(Engine!$M$2:$M$2201, Helpers!$B48)} -> 0.023082347 | R43: {=IF($E43="Hold", INDEX(Engine!$R$2:$R$2201, Helpers!$B48), INDEX(Engine!$AF$2:$AF$2201, Helpers!$B48))} -> 474.35487 | S43: {=INDEX(Engine!$R$2:$R$2201, Helpers!$B48) - $R43} -> 711.53231 | T43: =IFERROR($R43/$S43, 0) -> 0.66666667

Sheet Scenario Results
A1: Selected Scenario | B1: 2 | C1: {=INDEX(Model_Scenarios[SCENARIOS], $B$1)} -> Conservative
A3: SKU | B3: Recommendation | C3: Candidate Type | D3: Current Price | E3: Current Cost/Unit | F3: Current Volume | G3: Current GR | H3: Current GP | I3: Current GP Margin % | J3: V1 Price | K3: LTV Risk | L3: Scenario Name | M3: Best Score | N3: Adjusted Price | O3: Adjusted Difference $ | P3: Adjusted Difference % | Q3: Elasticity | R3: Adjusted Volume Change % | S3: Adjusted Volume | T3: Adjusted GR | U3: Adjusted GR Impact | V3: Adjusted GR Lift | W3: Adjusted COGS | X3: Adjusted COGS Impact | Y3: Adjusted COGS Lift | Z3: Adjusted GP | AA3: GP Impact $ | AB3: GP Lift % | AC3: Adjusted GP Margin % | AD3: GP Margin Impact % | AE3: GP Margin Lift | AF3: Price Aggressiveness | AG3: LTV Protected | AH3: LTV Sacrificed | AI3: LTV Protection-Risk Ratio
A4: {=INDEX(Model_Input[SKU], ROW()-3)} -> SKU-1000 | B4: {=INDEX(Model_Input[Tie-Breaking Recommendation], ROW()-3)} -> Raise | C4: {=INDEX(Model_Input[Candidate Type], ROW()-3)} -> Full | D4: {=INDEX(Model_Input[Current Price], ROW()-3)} -> 76.53 | E4: {=INDEX(Model_Input[Current Cost Per Unit], ROW()-3)} -> 52.96 | F4: {=INDEX(Model_Input[Current Volume], ROW()-3)} -> 24 | G4: {=INDEX(Model_Input[Current Gross Revenue], ROW()-3)} -> 1836.72 | H4: {=INDEX(Model_Input[Current Gross Profit], ROW()-3)} -> 565.68 | I4: {=INDEX(Model_Input[Current Gross Profit Margin %], ROW()-3)} -> 0.3079838 | J4: {=INDEX(Model_Input[V1 Suggested Price], ROW()-3)} -> 80.606323 | K4: {=INDEX(Model_Input[Total LTV at Risk], ROW()-3)} -> 1112.0932 | L4: =$C$1 -> Conservative | M4: =_xlfn.MAXIFS(CHOOSE($B$1, Engine!$AZ$2:$AZ$2201, Engine!$BA$2:$BA$2201, Engine!$BB$2:$BB$2201, Engine!$BC$2:$BC$2201, Engine!$BD$2:$BD$2201), Engine!$E$2:$E$2201, $A4) -> 5.4060316 | N4: {=INDEX(Engine!$T$2:$T$2201, MATCH(1, (Engine!$E$2:$E$2201=$A4) * (CHOOSE($B$1, Engine!$AZ$2:$AZ$2201, Engine!$BA$2:$BA$2201, Engine!$BB$2:$BB$2201, Engine!$BC$2:$BC$2201, Engine!$BD$2:$BD$2201)=$M4), 0))} -> 80.524796 | O4: =$N4-$D4 -> 3.9947964 | P4: =IFERROR($O4/$D4, 0) -> 0.05219909 | Q4: =IF($B4="Reduce", INDEX(Model_Assumptions[Values], 2), INDEX(Model_Assumptions[Values], 1)) -> -0.4 | R4: =$P4*$Q4 -> -0.020879636 | S4: =$F4*(1+$R4) -> 23.498889 | T4: =$S4*$N4 -> 1892.2432 | U4: =$T4-$G4 -> 55.52323 | V4: =IFERROR($U4/$G4, 0) -> 0.030229556 | W4: =$S4*$E4 -> 1244.5011 | X4: =$W4-($F4*$E4) -> -26.538853 | Y4: =IFERROR($X4/($F4*$E4), 0) -> -0.020879636 | Z4: =$T4-$W4 -> 647.74208 | AA4: =$Z4-$H4 -> 82.062083 | AB4: =IFERROR($AA4/$H4, 0) -> 0.14506803 | AC4: =IFERROR($Z4/$T4, 0) -> 0.34231439 | AD4: =$AC4-$I4 -> 0.034330591 | AE4: =$AD4 -> 0.034330591 | AF4: =IFERROR(($N4-$D4)/($J4-$D4), 0) -> 0.98 | AG4: =$K4*(1-$AF4) -> 22.241864 | AH4: =$K4-$AG4 -> 1089.8513 | AI4: =IFERROR($AG4/$AH4, 0) -> 0.020408163
A5: {=INDEX(Model_Input[SKU], ROW()-3)} -> SKU-1001 | B5: {=INDEX(Model_Input[Tie-Breaking Recommendation], ROW()-3)} -> Raise | C5: {=INDEX(Model_Input[Candidate Type], ROW()-3)} -> Full | D5: {=INDEX(Model_Input[Current Price], ROW()-3)} -> 53.26 | E5: {=INDEX(Model_Input[Current Cost Per Unit], ROW()-3)} -> 36.64 | F5: {=INDEX(Model_Input[Current Volume], ROW()-3)} -> 21 | G5: {=INDEX(Model_Input[Current Gross Revenue], ROW()-3)} -> 1118.46 | H5: {=INDEX(Model_Input[Current Gross Profit], ROW()-3)} -> 349.02 | I5: {=INDEX(Model_Input[Current Gross Profit Margin %], ROW()-3)} -> 0.31205407 | J5: {=INDEX(Model_Input[V1 Suggested Price], ROW()-3)} -> 57.563992 | K5: {=INDEX(Model_Input[Total LTV at Risk], ROW()-3)} -> 1487.03 | L5: =$C$1 -> Conservative | M5: =_xlfn.MAXIFS(CHOOSE($B$1, Engine!$AZ$2:$AZ$2201, Engine!$BA$2:$BA$2201, Engine!$BB$2:$BB$2201, Engine!$BC$2:$BC$2201, Engine!$BD$2:$BD$2201), Engine!$E$2:$E$2201, $A5) -> 3.9413985 | N5: {=INDEX(Engine!$T$2:$T$2201, MATCH(1, (Engine!$E$2:$E$2201=$A5) * (CHOOSE($B$1, Engine!$AZ$2:$AZ$2201, Engine!$BA$2:$BA$2201, Engine!$BB$2:$BB$2201, Engine!$BC$2:$BC$2201, Engine!$BD$2:$BD$2201)=$M5), 0))} -> 57.477912 | O5: =$N5-$D5 -> 4.217912 | P5: =IFERROR($O5/$D5, 0) -> 0.079194742 | Q5: =IF($B5="Reduce", INDEX(Model_Assumptions[Values], 2), INDEX(Model_Assumptions[Values], 1)) -> -0.4 | R5: =$P5*$Q5 -> -0.031677897 | S5: =$F5*(1+$R5) -> 20.334764 | T5: =$S5*$N5 -> 1168.7998 | U5: =$T5-$G5 -> 50.339785 | V5: =IFERROR($U5/$G5, 0) -> 0.045008122 | W5: =$S5*$E5 -> 745.06576 | X5: =$W5-($F5*$E5) -> -24.374241 | Y5: =IFERROR($X5/($F5*$E5), 0) -> -0.031677897 | Z5: =$T5-$W5 -> 423.73403 | AA5: =$Z5-$H5 -> 74.714025 | AB5: =IFERROR($AA5/$H5, 0) -> 0.21406803 | AC5: =IFERROR($Z5/$T5, 0) -> 0.36253773 | AD5: =$AC5-$I5 -> 0.05048366 | AE5: =$AD5 -> 0.05048366 | AF5: =IFERROR(($N5-$D5)/($J5-$D5), 0) -> 0.98 | AG5: =$K5*(1-$AF5) -> 29.7406 | AH5: =$K5-$AG5 -> 1457.2894 | AI5: =IFERROR($AG5/$AH5, 0) -> 0.020408163
A6: {=INDEX(Model_Input[SKU], ROW()-3)} -> SKU-1004 | B6: {=INDEX(Model_Input[Tie-Breaking Recommendation], ROW()-3)} -> Hold | C6: {=INDEX(Model_Input[Candidate Type], ROW()-3)} -> Full | D6: {=INDEX(Model_Input[Current Price], ROW()-3)} -> 18.39 | E6: {=INDEX(Model_Input[Current Cost Per Unit], ROW()-3)} -> 8.26 | F6: {=INDEX(Model_Input[Current Volume], ROW()-3)} -> 17 | G6: {=INDEX(Model_Input[Current Gross Revenue], ROW()-3)} -> 312.63 | H6: {=INDEX(Model_Input[Current Gross Profit], ROW()-3)} -> 172.21 | I6: {=INDEX(Model_Input[Current Gross Profit Margin %], ROW()-3)} -> 0.55084285 | J6: {=INDEX(Model_Input[V1 Suggested Price], ROW()-3)} -> 20.325622 | K6: {=INDEX(Model_Input[Total LTV at Risk], ROW()-3)} -> 1216.0707 | L6: =$C$1 -> Conservative | M6: =_xlfn.MAXIFS(CHOOSE($B$1, Engine!$AZ$2:$AZ$2201, Engine!$BA$2:$BA$2201, Engine!$BB$2:$BB$2201, Engine!$BC$2:$BC$2201, Engine!$BD$2:$BD$2201), Engine!$E$2:$E$2201, $A6) -> 3.9620157 | N6: {=INDEX(Engine!$T$2:$T$2201, MATCH(1, (Engine!$E$2:$E$2201=$A6) * (CHOOSE($B$1, Engine!$AZ$2:$AZ$2201, Engine!$BA$2:$BA$2201, Engine!$BB$2:$BB$2201, Engine!$BC$2:$BC$2201, Engine!$BD$2:$BD$2201)=$M6), 0))} -> 20.286909 | O6: =$N6-$D6 -> 1.8969092 | P6: =IFERROR($O6/$D6, 0) -> 0.10314895 | Q6: =IF($B6="Reduce", INDEX(Model_Assumptions[Values], 2), INDEX(Model_Assumptions[Values], 1)) -> -0.4 | R6: =$P6*$Q6 -> -0.041259581 | S6: =$F6*(1+$R6) -> 16.298587 | T6: =$S6*$N6 -> 330.64796 | U6: =$T6-$G6 -> 18.017958 | V6: =IFERROR($U6/$G6, 0) -> 0.057633488 | W6: =$S6*$E6 -> 134.62633 | X6: =$W6-($F6*$E6) -> -5.7936703 | Y6: =IFERROR($X6/($F6*$E6), 0) -> -0.041259581 | Z6: =$T6-$W6 -> 196.02163 | AA6: =$Z6-$H6 -> 23.811628 | AB6: =IFERROR($AA6/$H6, 0) -> 0.13827088 | AC6: =IFERROR($Z6/$T6, 0) -> 0.59284089 | AD6: =$AC6-$I6 -> 0.041998036 | AE6: =$AD6 -> 0.041998036 | AF6: =IFERROR(($N6-$D6)/($J6-$D6), 0) -> 0.98 | AG6: =$K6*(1-$AF6) -> 24.321413 | AH6: =$K6-$AG6 -> 1191.7493 | AI6: =IFERROR($AG6/$AH6, 0) -> 0.020408163
A7: {=INDEX(Model_Input[SKU], ROW()-3)} -> SKU-1005 | B7: {=INDEX(Model_Input[Tie-Breaking Recommendation], ROW()-3)} -> Raise | C7: {=INDEX(Model_Input[Candidate Type], ROW()-3)} -> Full | D7: {=INDEX(Model_Input[Current Price], ROW()-3)} -> 29.62 | E7: {=INDEX(Model_Input[Current Cost Per Unit], ROW()-3)} -> 19.42 | F7: {=INDEX(Model_Input[Current Volume], ROW()-3)} -> 46 | G7: {=INDEX(Model_Input[Current Gross Revenue], ROW()-3)} -> 1362.52 | H7: {=INDEX(Model_Input[Current Gross Profit], ROW()-3)} -> 469.2 | I7: {=INDEX(Model_Input[Current Gross Profit Margin %], ROW()-3)} -> 0.34436192 | J7: {=INDEX(Model_Input[V1 Suggested Price], ROW()-3)} -> 28.258195 | K7: {=INDEX(Model_Input[Total LTV at Risk], ROW()-3)} -> 1171.8239 | L7: =$C$1 -> Conservative | M7: =_xlfn.MAXIFS(CHOOSE($B$1, Engine!$AZ$2:$AZ$2201, Engine!$BA$2:$BA$2201, Engine!$BB$2:$BB$2201, Engine!$BC$2:$BC$2201, Engine!$BD$2:$BD$2201), Engine!$E$2:$E$2201, $A7) -> 5.3284842 | N7: {=INDEX(Engine!$T$2:$T$2201, MATCH(1, (Engine!$E$2:$E$2201=$A7) * (CHOOSE($B$1, Engine!$AZ$2:$AZ$2201, Engine!$BA$2:$BA$2201, Engine!$BB$2:$BB$2201, Engine!$BC$2:$BC$2201, Engine!$BD$2:$BD$2201)=$M7), 0))} -> 29.62 | O7: =$N7-$D7 -> 0 | P7: =IFERROR($O7/$D7, 0) -> 0 | Q7: =IF($B7="Reduce", INDEX(Model_Assumptions[Values], 2), INDEX(Model_Assumptions[Values], 1)) -> -0.4 | R7: =$P7*$Q7 -> 0 | S7: =$F7*(1+$R7) -> 46 | T7: =$S7*$N7 -> 1362.52 | U7: =$T7-$G7 -> 0 | V7: =IFERROR($U7/$G7, 0) -> 0 | W7: =$S7*$E7 -> 893.32 | X7: =$W7-($F7*$E7) -> 0 | Y7: =IFERROR($X7/($F7*$E7), 0) -> 0 | Z7: =$T7-$W7 -> 469.2 | AA7: =$Z7-$H7 -> 0 | AB7: =IFERROR($AA7/$H7, 0) -> 0 | AC7: =IFERROR($Z7/$T7, 0) -> 0.34436192 | AD7: =$AC7-$I7 -> 0 | AE7: =$AD7 -> 0 | AF7: =IFERROR(($N7-$D7)/($J7-$D7), 0) -> 0 | AG7: =$K7*(1-$AF7) -> 1171.8239 | AH7: =$K7-$AG7 -> 0 | AI7: =IFERROR($AG7/$AH7, 0) -> 0
A8: {=INDEX(Model_Input[SKU], ROW()-3)} -> SKU-1006 | B8: {=INDEX(Model_Input[Tie-Breaking Recommendation], ROW()-3)} -> Hold | C8: {=INDEX(Model_Input[Candidate Type], ROW()-3)} -> Full | D8: {=INDEX(Model_Input[Current Price], ROW()-3)} -> 113.18 | E8: {=INDEX(Model_Input[Current Cost Per Unit], ROW()-3)} -> 39.01 | F8: {=INDEX(Model_Input[Current Volume], ROW()-3)} -> 24 | G8: {=INDEX(Model_Input[Current Gross Revenue], ROW()-3)} -> 2716.32 | H8: {=INDEX(Model_Input[Current Gross Profit], ROW()-3)} -> 1780.08 | I8: {=INDEX(Model_Input[Current Gross Profit Margin %], ROW()-3)} -> 0.6553278 | J8: {=INDEX(Model_Input[V1 Suggested Price], ROW()-3)} -> 122.07351 | K8: {=INDEX(Model_Input[Total LTV at Risk], ROW()-3)} -> 1378.1368 | L8: =$C$1 -> Conservative | M8: =_xlfn.MAXIFS(CHOOSE($B$1, Engine!$AZ$2:$AZ$2201, Engine!$BA$2:$BA$2201, Engine!$BB$2:$BB$2201, Engine!$BC$2:$BC$2201, Engine!$BD$2:$BD$2201), Engine!$E$2:$E$2201, $A8) -> 4.0560621 | N8: {=INDEX(Engine!$T$2:$T$2201, MATCH(1, (Engine!$E$2:$E$2201=$A8) * (CHOOSE($B$1, Engine!$AZ$2:$AZ$2201, Engine!$BA$2:$BA$2201, Engine!$BB$2:$BB$2201, Engine!$BC$2:$BC$2201, Engine!$BD$2:$BD$2201)=$M8), 0))} -> 121.89564 | O8: =$N8-$D8 -> 8.715642 | P8: =IFERROR($O8/$D8, 0) -> 0.077006909 | Q8: =IF($B8="Reduce", INDEX(Model_Assumptions[Values], 2), INDEX(Model_Assumptions[Values], 1)) -> -0.4 | R8: =$P8*$Q8 -> -0.030802764 | S8: =$F8*(1+$R8) -> 23.260734 | T8: =$S8*$N8 -> 2835.3821 | U8: =$T8-$G8 -> 119.06206 | V8: =IFERROR($U8/$G8, 0) -> 0.04383212 | W8: =$S8*$E8 -> 907.40122 | X8: =$W8-($F8*$E8) -> -28.83878 | Y8: =IFERROR($X8/($F8*$E8), 0) -> -0.030802764 | Z8: =$T8-$W8 -> 1927.9808 | AA8: =$Z8-$H8 -> 147.90084 | AB8: =IFERROR($AA8/$H8, 0) -> 0.083086627 | AC8: =IFERROR($Z8/$T8, 0) -> 0.67997215 | AD8: =$AC8-$I8 -> 0.024644355 | AE8: =$AD8 -> 0.024644355 | AF8: =IFERROR(($N8-$D8)/($J8-$D8), 0) -> 0.98 | AG8: =$K8*(1-$AF8) -> 27.562736 | AH8: =$K8-$AG8 -> 1350.5741 | AI8: =IFERROR($AG8/$AH8, 0) -> 0.020408163
A9: {=INDEX(Model_Input[SKU], ROW()-3)} -> SKU-1009 | B9: {=INDEX(Model_Input[Tie-Breaking Recommendation], ROW()-3)} -> Raise | C9: {=INDEX(Model_Input[Candidate Type], ROW()-3)} -> Full | D9: {=INDEX(Model_Input[Current Price], ROW()-3)} -> 177.91 | E9: {=INDEX(Model_Input[Current Cost Per Unit], ROW()-3)} -> 73.49 | F9: {=INDEX(Model_Input[Current Volume], ROW()-3)} -> 36 | G9: {=INDEX(Model_Input[Current Gross Revenue], ROW()-3)} -> 6404.76 | H9: {=INDEX(Model_Input[Current Gross Profit], ROW()-3)} -> 3759.12 | I9: {=INDEX(Model_Input[Current Gross Profit Margin %], ROW()-3)} -> 0.58692597 | J9: {=INDEX(Model_Input[V1 Suggested Price], ROW()-3)} -> 210.36242 | K9: {=INDEX(Model_Input[Total LTV at Risk], ROW()-3)} -> 1987.1738 | L9: =$C$1 -> Conservative | M9: =_xlfn.MAXIFS(CHOOSE($B$1, Engine!$AZ$2:$AZ$2201, Engine!$BA$2:$BA$2201, Engine!$BB$2:$BB$2201, Engine!$BC$2:$BC$2201, Engine!$BD$2:$BD$2201), Engine!$E$2:$E$2201, $A9) -> 2.2574333 | N9: {=INDEX(Engine!$T$2:$T$2201, MATCH(1, (Engine!$E$2:$E$2201=$A9) * (CHOOSE($B$1, Engine!$AZ$2:$AZ$2201, Engine!$BA$2:$BA$2201, Engine!$BB$2:$BB$2201, Engine!$BC$2:$BC$2201, Engine!$BD$2:$BD$2201)=$M9), 0))} -> 201.92479 | O9: =$N9-$D9 -> 24.014791 | P9: =IFERROR($O9/$D9, 0) -> 0.13498281 | Q9: =IF($B9="Reduce", INDEX(Model_Assumptions[Values], 2), INDEX(Model_Assumptions[Values], 1)) -> -0.4 | R9: =$P9*$Q9 -> -0.053993123 | S9: =$F9*(1+$R9) -> 34.056248 | T9: =$S9*$N9 -> 6876.8007 | U9: =$T9-$G9 -> 472.04068 | V9: =IFERROR($U9/$G9, 0) -> 0.073701541 | W9: =$S9*$E9 -> 2502.7936 | X9: =$W9-($F9*$E9) -> -142.84637 | Y9: =IFERROR($X9/($F9*$E9), 0) -> -0.053993123 | Z9: =$T9-$W9 -> 4374.007 | AA9: =$Z9-$H9 -> 614.88705 | AB9: =IFERROR($AA9/$H9, 0) -> 0.16357207 | AC9: =IFERROR($Z9/$T9, 0) -> 0.63605261 | AD9: =$AC9-$I9 -> 0.04912664 | AE9: =$AD9 -> 0.04912664 | AF9: =IFERROR(($N9-$D9)/($J9-$D9), 0) -> 0.74 | AG9: =$K9*(1-$AF9) -> 516.66518 | AH9: =$K9-$AG9 -> 1470.5086 | AI9: =IFERROR($AG9/$AH9, 0) -> 0.35135135
A10: {=INDEX(Model_Input[SKU], ROW()-3)} -> SKU-1010 | B10: {=INDEX(Model_Input[Tie-Breaking Recommendation], ROW()-3)} -> Raise | C10: {=INDEX(Model_Input[Candidate Type], ROW()-3)} -> Full | D10: {=INDEX(Model_Input[Current Price], ROW()-3)} -> 45.86 | E10: {=INDEX(Model_Input[Current Cost Per Unit], ROW()-3)} -> 24.87 | F10: {=INDEX(Model_Input[Current Volume], ROW()-3)} -> 42 | G10: {=INDEX(Model_Input[Current Gross Revenue], ROW()-3)} -> 1926.12 | H10: {=INDEX(Model_Input[Current Gross Profit], ROW()-3)} -> 881.58 | I10: {=INDEX(Model_Input[Current Gross Profit Margin %], ROW()-3)} -> 0.45769734 | J10: {=INDEX(Model_Input[V1 Suggested Price], ROW()-3)} -> 57.591702 | K10: {=INDEX(Model_Input[Total LTV at Risk], ROW()-3)} -> 1838.4437 | L10: =$C$1 -> Conservative | M10: =_xlfn.MAXIFS(CHOOSE($B$1, Engine!$AZ$2:$AZ$2201, Engine!$BA$2:$BA$2201, Engine!$BB$2:$BB$2201, Engine!$BC$2:$BC$2201, Engine!$BD$2:$BD$2201), Engine!$E$2:$E$2201, $A10) -> 2.3527087 | N10: {=INDEX(Engine!$T$2:$T$2201, MATCH(1, (Engine!$E$2:$E$2201=$A10) * (CHOOSE($B$1, Engine!$AZ$2:$AZ$2201, Engine!$BA$2:$BA$2201, Engine!$BB$2:$BB$2201, Engine!$BC$2:$BC$2201, Engine!$BD$2:$BD$2201)=$M10), 0))} -> 50.552681 | O10: =$N10-$D10 -> 4.6926806 | P10: =IFERROR($O10/$D10, 0) -> 0.10232622 | Q10: =IF($B10="Reduce", INDEX(Model_Assumptions[Values], 2), INDEX(Model_Assumptions[Values], 1)) -> -0.4 | R10: =$P10*$Q10 -> -0.04093049 | S10: =$F10*(1+$R10) -> 40.280919 | T10: =$S10*$N10 -> 2036.3085 | U10: =$T10-$G10 -> 110.18846 | V10: =IFERROR($U10/$G10, 0) -> 0.057207472 | W10: =$S10*$E10 -> 1001.7865 | X10: =$W10-($F10*$E10) -> -42.753534 | Y10: =IFERROR($X10/($F10*$E10), 0) -> -0.04093049 | Z10: =$T10-$W10 -> 1034.522 | AA10: =$Z10-$H10 -> 152.94199 | AB10: =IFERROR($AA10/$H10, 0) -> 0.17348623 | AC10: =IFERROR($Z10/$T10, 0) -> 0.50803796 | AD10: =$AC10-$I10 -> 0.050340618 | AE10: =$AD10 -> 0.050340618 | AF10: =IFERROR(($N10-$D10)/($J10-$D10), 0) -> 0.4 | AG10: =$K10*(1-$AF10) -> 1103.0662 | AH10: =$K10-$AG10 -> 735.37746 | AI10: =IFERROR($AG10/$AH10, 0) -> 1.5
A11: {=INDEX(Model_Input[SKU], ROW()-3)} -> SKU-1011 | B11: {=INDEX(Model_Input[Tie-Breaking Recommendation], ROW()-3)} -> Raise | C11: {=INDEX(Model_Input[Candidate Type], ROW()-3)} -> Full | D11: {=INDEX(Model_Input[Current Price], ROW()-3)} -> 67.56 | E11: {=INDEX(Model_Input[Current Cost Per Unit], ROW()-3)} -> 43.21 | F11: {=INDEX(Model_Input[Current Volume], ROW()-3)} -> 22 | G11: {=INDEX(Model_Input[Current Gross Revenue], ROW()-3)} -> 1486.32 | H11: {=INDEX(Model_Input[Current Gross Profit], ROW()-3)} -> 535.7 | I11: {=INDEX(Model_Input[Current Gross Profit Margin %], ROW()-3)} -> 0.36042037 | J11: {=INDEX(Model_Input[V1 Suggested Price], ROW()-3)} -> 74.848492 | K11: {=INDEX(Model_Input[Total LTV at Risk], ROW()-3)} -> 1511.5432 | L11: =$C$1 -> Conservative | M11: =_xlfn.MAXIFS(CHOOSE($B$1, Engine!$AZ$2:$AZ$2201, Engine!$BA$2:$BA$2201, Engine!$BB$2:$BB$2201, Engine!$BC$2:$BC$2201, Engine!$BD$2:$BD$2201), Engine!$E$2:$E$2201, $A11) -> 3.3544814 | N11: {=INDEX(Engine!$T$2:$T$2201, MATCH(1, (Engine!$E$2:$E$2201=$A11) * (CHOOSE($B$1, Engine!$AZ$2:$AZ$2201, Engine!$BA$2:$BA$2201, Engine!$BB$2:$BB$2201, Engine!$BC$2:$BC$2201, Engine!$BD$2:$BD$2201)=$M11), 0))} -> 74.702723 | O11: =$N11-$D11 -> 7.1427226 | P11: =IFERROR($O11/$D11, 0) -> 0.10572414 | Q11: =IF($B11="Reduce", INDEX(Model_Assumptions[Values], 2), INDEX(Model_Assumptions[Values], 1)) -> -0.4 | R11: =$P11*$Q11 -> -0.042289654 | S11: =$F11*(1+$R11) -> 21.069628 | T11: =$S11*$N11 -> 1573.9585 | U11: =$T11-$G11 -> 87.638547 | V11: =IFERROR($U11/$G11, 0) -> 0.058963444 | W11: =$S11*$E11 -> 910.41861 | X11: =$W11-($F11*$E11) -> -40.201391 | Y11: =IFERROR($X11/($F11*$E11), 0) -> -0.042289654 | Z11: =$T11-$W11 -> 663.53994 | AA11: =$Z11-$H11 -> 127.83994 | AB11: =IFERROR($AA11/$H11, 0) -> 0.23864091 | AC11: =IFERROR($Z11/$T11, 0) -> 0.42157396 | AD11: =$AC11-$I11 -> 0.061153593 | AE11: =$AD11 -> 0.061153593 | AF11: =IFERROR(($N11-$D11)/($J11-$D11), 0) -> 0.98 | AG11: =$K11*(1-$AF11) -> 30.230864 | AH11: =$K11-$AG11 -> 1481.3123 | AI11: =IFERROR($AG11/$AH11, 0) -> 0.020408163
A12: {=INDEX(Model_Input[SKU], ROW()-3)} -> SKU-1012 | B12: {=INDEX(Model_Input[Tie-Breaking Recommendation], ROW()-3)} -> Raise | C12: {=INDEX(Model_Input[Candidate Type], ROW()-3)} -> Full | D12: {=INDEX(Model_Input[Current Price], ROW()-3)} -> 20.37 | E12: {=INDEX(Model_Input[Current Cost Per Unit], ROW()-3)} -> 9.76 | F12: {=INDEX(Model_Input[Current Volume], ROW()-3)} -> 15 | G12: {=INDEX(Model_Input[Current Gross Revenue], ROW()-3)} -> 305.55 | H12: {=INDEX(Model_Input[Current Gross Profit], ROW()-3)} -> 159.15 | I12: {=INDEX(Model_Input[Current Gross Profit Margin %], ROW()-3)} -> 0.52086402 | J12: {=INDEX(Model_Input[V1 Suggested Price], ROW()-3)} -> 20.226862 | K12: {=INDEX(Model_Input[Total LTV at Risk], ROW()-3)} -> 464.13364 | L12: =$C$1 -> Conservative | M12: =_xlfn.MAXIFS(CHOOSE($B$1, Engine!$AZ$2:$AZ$2201, Engine!$BA$2:$BA$2201, Engine!$BB$2:$BB$2201, Engine!$BC$2:$BC$2201, Engine!$BD$2:$BD$2201), Engine!$E$2:$E$2201, $A12) -> 5.3473478 | N12: {=INDEX(Engine!$T$2:$T$2201, MATCH(1, (Engine!$E$2:$E$2201=$A12) * (CHOOSE($B$1, Engine!$AZ$2:$AZ$2201, Engine!$BA$2:$BA$2201, Engine!$BB$2:$BB$2201, Engine!$BC$2:$BC$2201, Engine!$BD$2:$BD$2201)=$M12), 0))} -> 20.37 | O12: =$N12-$D12 -> 0 | P12: =IFERROR($O12/$D12, 0) -> 0 | Q12: =IF($B12="Reduce", INDEX(Model_Assumptions[Values], 2), INDEX(Model_Assumptions[Values], 1)) -> -0.4 | R12: =$P12*$Q12 -> 0 | S12: =$F12*(1+$R12) -> 15 | T12: =$S12*$N12 -> 305.55 | U12: =$T12-$G12 -> 0 | V12: =IFERROR($U12/$G12, 0) -> 0 | W12: =$S12*$E12 -> 146.4 | X12: =$W12-($F12*$E12) -> 0 | Y12: =IFERROR($X12/($F12*$E12), 0) -> 0 | Z12: =$T12-$W12 -> 159.15 | AA12: =$Z12-$H12 -> 0 | AB12: =IFERROR($AA12/$H12, 0) -> 0 | AC12: =IFERROR($Z12/$T12, 0) -> 0.52086402 | AD12: =$AC12-$I12 -> 0 | AE12: =$AD12 -> 0 | AF12: =IFERROR(($N12-$D12)/($J12-$D12), 0) -> 0 | AG12: =$K12*(1-$AF12) -> 464.13364 | AH12: =$K12-$AG12 -> 0 | AI12: =IFERROR($AG12/$AH12, 0) -> 0
A13: {=INDEX(Model_Input[SKU], ROW()-3)} -> SKU-1013 | B13: {=INDEX(Model_Input[Tie-Breaking Recommendation], ROW()-3)} -> Raise | C13: {=INDEX(Model_Input[Candidate Type], ROW()-3)} -> Constrained | D13: {=INDEX(Model_Input[Current Price], ROW()-3)} -> 84.95 | E13: {=INDEX(Model_Input[Current Cost Per Unit], ROW()-3)} -> 53.07 | F13: {=INDEX(Model_Input[Current Volume], ROW()-3)} -> 36 | G13: {=INDEX(Model_Input[Current Gross Revenue], ROW()-3)} -> 3058.2 | H13: {=INDEX(Model_Input[Current Gross Profit], ROW()-3)} -> 1147.68 | I13: {=INDEX(Model_Input[Current Gross Profit Margin %], ROW()-3)} -> 0.37527958 | J13: {=INDEX(Model_Input[V1 Suggested Price], ROW()-3)} -> 84.95 | K13: {=INDEX(Model_Input[Total LTV at Risk], ROW()-3)} -> 1153.7475 | L13: =$C$1 -> Conservative | M13: =_xlfn.MAXIFS(CHOOSE($B$1, Engine!$AZ$2:$AZ$2201, Engine!$BA$2:$BA$2201, Engine!$BB$2:$BB$2201, Engine!$BC$2:$BC$2201, Engine!$BD$2:$BD$2201), Engine!$E$2:$E$2201, $A13) -> 2.8045227 | N13: {=INDEX(Engine!$T$2:$T$2201, MATCH(1, (Engine!$E$2:$E$2201=$A13) * (CHOOSE($B$1, Engine!$AZ$2:$AZ$2201, Engine!$BA$2:$BA$2201, Engine!$BB$2:$BB$2201, Engine!$BC$2:$BC$2201, Engine!$BD$2:$BD$2201)=$M13), 0))} -> 84.95 | O13: =$N13-$D13 -> 0 | P13: =IFERROR($O13/$D13, 0) -> 0 | Q13: =IF($B13="Reduce", INDEX(Model_Assumptions[Values], 2), INDEX(Model_Assumptions[Values], 1)) -> -0.4 | R13: =$P13*$Q13 -> 0 | S13: =$F13*(1+$R13) -> 36 | T13: =$S13*$N13 -> 3058.2 | U13: =$T13-$G13 -> 0 | V13: =IFERROR($U13/$G13, 0) -> 0 | W13: =$S13*$E13 -> 1910.52 | X13: =$W13-($F13*$E13) -> 0 | Y13: =IFERROR($X13/($F13*$E13), 0) -> 0 | Z13: =$T13-$W13 -> 1147.68 | AA13: =$Z13-$H13 -> 0 | AB13: =IFERROR($AA13/$H13, 0) -> 0 | AC13: =IFERROR($Z13/$T13, 0) -> 0.37527958 | AD13: =$AC13-$I13 -> 0 | AE13: =$AD13 -> 0 | AF13: =IFERROR(($N13-$D13)/($J13-$D13), 0) -> 0 | AG13: =$K13*(1-$AF13) -> 1153.7475 | AH13: =$K13-$AG13 -> 0 | AI13: =IFERROR($AG13/$AH13, 0) -> 0
A14: {=INDEX(Model_Input[SKU], ROW()-3)} -> SKU-1014 | B14: {=INDEX(Model_Input[Tie-Breaking Recommendation], ROW()-3)} -> Raise | C14: {=INDEX(Model_Input[Candidate Type], ROW()-3)} -> Full | D14: {=INDEX(Model_Input[Current Price], ROW()-3)} -> 143.8 | E14: {=INDEX(Model_Input[Current Cost Per Unit], ROW()-3)} -> 62.15 | F14: {=INDEX(Model_Input[Current Volume], ROW()-3)} -> 29 | G14: {=INDEX(Model_Input[Current Gross Revenue], ROW()-3)} -> 4170.2 | H14: {=INDEX(Model_Input[Current Gross Profit], ROW()-3)} -> 2367.85 | I14: {=INDEX(Model_Input[Current Gross Profit Margin %], ROW()-3)} -> 0.5678025 | J14: {=INDEX(Model_Input[V1 Suggested Price], ROW()-3)} -> 176.09453 | K14: {=INDEX(Model_Input[Total LTV at Risk], ROW()-3)} -> 1207.1798 | L14: =$C$1 -> Conservative | M14: =_xlfn.MAXIFS(CHOOSE($B$1, Engine!$AZ$2:$AZ$2201, Engine!$BA$2:$BA$2201, Engine!$BB$2:$BB$2201, Engine!$BC$2:$BC$2201, Engine!$BD$2:$BD$2201), Engine!$E$2:$E$2201, $A14) -> 3.3829177 | N14: {=INDEX(Engine!$T$2:$T$2201, MATCH(1, (Engine!$E$2:$E$2201=$A14) * (CHOOSE($B$1, Engine!$AZ$2:$AZ$2201, Engine!$BA$2:$BA$2201, Engine!$BB$2:$BB$2201, Engine!$BC$2:$BC$2201, Engine!$BD$2:$BD$2201)=$M14), 0))} -> 175.44864 | O14: =$N14-$D14 -> 31.648638 | P14: =IFERROR($O14/$D14, 0) -> 0.22008789 | Q14: =IF($B14="Reduce", INDEX(Model_Assumptions[Values], 2), INDEX(Model_Assumptions[Values], 1)) -> -0.4 | R14: =$P14*$Q14 -> -0.088035154 | S14: =$F14*(1+$R14) -> 26.446981 | T14: =$S14*$N14 -> 4640.0867 | U14: =$T14-$G14 -> 469.88671 | V14: =IFERROR($U14/$G14, 0) -> 0.11267726 | W14: =$S14*$E14 -> 1643.6798 | X14: =$W14-($F14*$E14) -> -158.67016 | Y14: =IFERROR($X14/($F14*$E14), 0) -> -0.088035154 | Z14: =$T14-$W14 -> 2996.4069 | AA14: =$Z14-$H14 -> 628.55687 | AB14: =IFERROR($AA14/$H14, 0) -> 0.26545468 | AC14: =IFERROR($Z14/$T14, 0) -> 0.64576528 | AD14: =$AC14-$I14 -> 0.077962772 | AE14: =$AD14 -> 0.077962772 | AF14: =IFERROR(($N14-$D14)/($J14-$D14), 0) -> 0.98 | AG14: =$K14*(1-$AF14) -> 24.143596 | AH14: =$K14-$AG14 -> 1183.0362 | AI14: =IFERROR($AG14/$AH14, 0) -> 0.020408163
A15: {=INDEX(Model_Input[SKU], ROW()-3)} -> SKU-1017 | B15: {=INDEX(Model_Input[Tie-Breaking Recommendation], ROW()-3)} -> Raise | C15: {=INDEX(Model_Input[Candidate Type], ROW()-3)} -> Full | D15: {=INDEX(Model_Input[Current Price], ROW()-3)} -> 63.19 | E15: {=INDEX(Model_Input[Current Cost Per Unit], ROW()-3)} -> 41.45 | F15: {=INDEX(Model_Input[Current Volume], ROW()-3)} -> 19 | G15: {=INDEX(Model_Input[Current Gross Revenue], ROW()-3)} -> 1200.61 | H15: {=INDEX(Model_Input[Current Gross Profit], ROW()-3)} -> 413.06 | I15: {=INDEX(Model_Input[Current Gross Profit Margin %], ROW()-3)} -> 0.34404178 | J15: {=INDEX(Model_Input[V1 Suggested Price], ROW()-3)} -> 64.147136 | K15: {=INDEX(Model_Input[Total LTV at Risk], ROW()-3)} -> 1170.2078 | L15: =$C$1 -> Conservative | M15: =_xlfn.MAXIFS(CHOOSE($B$1, Engine!$AZ$2:$AZ$2201, Engine!$BA$2:$BA$2201, Engine!$BB$2:$BB$2201, Engine!$BC$2:$BC$2201, Engine!$BD$2:$BD$2201), Engine!$E$2:$E$2201, $A15) -> 2.3147725 | N15: {=INDEX(Engine!$T$2:$T$2201, MATCH(1, (Engine!$E$2:$E$2201=$A15) * (CHOOSE($B$1, Engine!$AZ$2:$AZ$2201, Engine!$BA$2:$BA$2201, Engine!$BB$2:$BB$2201, Engine!$BC$2:$BC$2201, Engine!$BD$2:$BD$2201)=$M15), 0))} -> 64.127993 | O15: =$N15-$D15 -> 0.9379932 | P15: =IFERROR($O15/$D15, 0) -> 0.014844013 | Q15: =IF($B15="Reduce", INDEX(Model_Assumptions[Values], 2), INDEX(Model_Assumptions[Values], 1)) -> -0.4 | R15: =$P15*$Q15 -> -0.0059376053 | S15: =$F15*(1+$R15) -> 18.887185 | T15: =$S15*$N15 -> 1211.1973 | U15: =$T15-$G15 -> 10.587303 | V15: =IFERROR($U15/$G15, 0) -> 0.0088182701 | W15: =$S15*$E15 -> 782.87384 | X15: =$W15-($F15*$E15) -> -4.6761611 | Y15: =IFERROR($X15/($F15*$E15), 0) -> -0.0059376053 | Z15: =$T15-$W15 -> 428.32346 | AA15: =$Z15-$H15 -> 15.263464 | AB15: =IFERROR($AA15/$H15, 0) -> 0.036952173 | AC15: =IFERROR($Z15/$T15, 0) -> 0.35363641 | AD15: =$AC15-$I15 -> 0.0095946298 | AE15: =$AD15 -> 0.0095946298 | AF15: =IFERROR(($N15-$D15)/($J15-$D15), 0) -> 0.98 | AG15: =$K15*(1-$AF15) -> 23.404155 | AH15: =$K15-$AG15 -> 1146.8036 | AI15: =IFERROR($AG15/$AH15, 0) -> 0.020408163
... A45: {=INDEX(Model_Input[SKU], ROW()-3)} -> SKU-1049 | B45: {=INDEX(Model_Input[Tie-Breaking Recommendation], ROW()-3)} -> Raise | C45: {=INDEX(Model_Input[Candidate Type], ROW()-3)} -> Full | D45: {=INDEX(Model_Input[Current Price], ROW()-3)} -> 99.75 | E45: {=INDEX(Model_Input[Current Cost Per Unit], ROW()-3)} -> 38.13 | F45: {=INDEX(Model_Input[Current Volume], ROW()-3)} -> 34 | G45: {=INDEX(Model_Input[Current Gross Revenue], ROW()-3)} -> 3391.5 | H45: {=INDEX(Model_Input[Current Gross Profit], ROW()-3)} -> 2095.08 | I45: {=INDEX(Model_Input[Current Gross Profit Margin %], ROW()-3)} -> 0.61774436 | J45: {=INDEX(Model_Input[V1 Suggested Price], ROW()-3)} -> 110.43409 | K45: {=INDEX(Model_Input[Total LTV at Risk], ROW()-3)} -> 1533.9834 | L45: =$C$1 -> Conservative | M45: =_xlfn.MAXIFS(CHOOSE($B$1, Engine!$AZ$2:$AZ$2201, Engine!$BA$2:$BA$2201, Engine!$BB$2:$BB$2201, Engine!$BC$2:$BC$2201, Engine!$BD$2:$BD$2201), Engine!$E$2:$E$2201, $A45) -> 2.4263733 | N45: {=INDEX(Engine!$T$2:$T$2201, MATCH(1, (Engine!$E$2:$E$2201=$A45) * (CHOOSE($B$1, Engine!$AZ$2:$AZ$2201, Engine!$BA$2:$BA$2201, Engine!$BB$2:$BB$2201, Engine!$BC$2:$BC$2201, Engine!$BD$2:$BD$2201)=$M45), 0))} -> 110.22041 | O45: =$N45-$D45 -> 10.470409 | P45: =IFERROR($O45/$D45, 0) -> 0.10496651 | Q45: =IF($B45="Reduce", INDEX(Model_Assumptions[Values], 2), INDEX(Model_Assumptions[Values], 1)) -> -0.4 | R45: =$P45*$Q45 -> -0.041986604 | S45: =$F45*(1+$R45) -> 32.572455 | T45: =$S45*$N45 -> 3590.1494 | U45: =$T45-$G45 -> 198.64938 | V45: =IFERROR($U45/$G45, 0) -> 0.058572719 | W45: =$S45*$E45 -> 1241.9877 | X45: =$W45-($F45*$E45) -> -54.432273 | Y45: =IFERROR($X45/($F45*$E45), 0) -> -0.041986604 | Z45: =$T45-$W45 -> 2348.1616 | AA45: =$Z45-$H45 -> 253.08165 | AB45: =IFERROR($AA45/$H45, 0) -> 0.12079808 | AC45: =IFERROR($Z45/$T45, 0) -> 0.65405681 | AD45: =$AC45-$I45 -> 0.036312449 | AE45: =$AD45 -> 0.036312449 | AF45: =IFERROR(($N45-$D45)/($J45-$D45), 0) -> 0.98 | AG45: =$K45*(1-$AF45) -> 30.679668 | AH45: =$K45-$AG45 -> 1503.3037 | AI45: =IFERROR($AG45/$AH45, 0) -> 0.020408163
P48: =MIN(P4:P47) -> 0
P49: =MAX(P4:P47) -> 0.24971705

Sheet Helpers
A1: SELECTION ASSUMPTIONS | B1: Values
A2: Best Outcome GR Weight | B2: 1
A3: Best Outcome GP Weight | B3: 1.2
A4: Minimum Viable LTV Protection % | B4: 0.4
A6: SKU | B6: Best Row | C6: Best Combined Score | D6: Best Test Price | E6: GR Lift % at Best | F6: GP Lift % at Best | G6: LTV Protection % at Best
A7: {=INDEX(Model_Input[SKU], ROW()-6)} -> SKU-1000 | B7: {=_xlfn.LET( _xlpm.sku, $A7, _xlpm.matches, (Engine!$E$2:$E$2201=_xlpm.sku), _xlpm.gr_lift, IFERROR(IF(_xlpm.matches, Engine!$Z$2:$Z$2201 / Engine!$K$2:$K$2201, -999), -999), _xlpm.gp_lift, IFERROR(IF(_xlpm.matches, Engine!$AA$2:$AA$2201 / Engine!$L$2:$L$2201, -999), -999), _xlpm.ltv_prot, IFERROR(IF(_xlpm.matches, Engine!$AF$2:$AF$2201 / Engine!$R$2:$R$2201, 0), 0), _xlpm.combined, IF(_xlpm.ltv_prot >= INDEX(Selection_Assumptions[Values],3), INDEX(Selection_Assumptions[Values],1)*_xlpm.gr_lift + INDEX(Selection_Assumptions[Values],2)*_xlpm.gp_lift, -999), MATCH(MAX(_xlpm.combined), IF(_xlpm.matches, _xlpm.combined), 0) )} -> 31 | C7: {=_xlfn.LET( _xlpm.sku, $A7, _xlpm.matches, (Engine!$E$2:$E$2201=_xlpm.sku), _xlpm.gr_lift, IFERROR(IF(_xlpm.matches, Engine!$Z$2:$Z$2201 / Engine!$K$2:$K$2201, -999), -999), _xlpm.gp_lift, IFERROR(IF(_xlpm.matches, Engine!$AA$2:$AA$2201 / Engine!$L$2:$L$2201, -999), -999), _xlpm.ltv_prot, IFERROR(IF(_xlpm.matches, Engine!$AF$2:$AF$2201 / Engine!$R$2:$R$2201, 0), 0), _xlpm.combined, IF(_xlpm.ltv_prot >= INDEX(Selection_Assumptions[Values],3), INDEX(Selection_Assumptions[Values],1)*_xlpm.gr_lift + INDEX(Selection_Assumptions[Values],2)*_xlpm.gp_lift, -999), MAX(_xlpm.combined) )} -> 0.12635537 | D7: {=INDEX(Engine!$T$2:$T$2201, $B7)} -> 78.975794 | E7: {=IFERROR(INDEX(Engine!$Z$2:$Z$2201, $B7) / INDEX(Engine!$K$2:$K$2201, $B7), 0)} -> 0.018766635 | F7: {=IFERROR(INDEX(Engine!$AA$2:$AA$2201, $B7) / INDEX(Engine!$L$2:$L$2201, $B7), 0)} -> 0.08965728 | G7: {=IFERROR(INDEX(Engine!$AF$2:$AF$2201, $B7) / INDEX(Engine!$R$2:$R$2201, $B7), 0)} -> 0.4
A8: {=INDEX(Model_Input[SKU], ROW()-6)} -> SKU-1001 | B8: {=_xlfn.LET( _xlpm.sku, $A8, _xlpm.matches, (Engine!$E$2:$E$2201=_xlpm.sku), _xlpm.gr_lift, IFERROR(IF(_xlpm.matches, Engine!$Z$2:$Z$2201 / Engine!$K$2:$K$2201, -999), -999), _xlpm.gp_lift, IFERROR(IF(_xlpm.matches, Engine!$AA$2:$AA$2201 / Engine!$L$2:$L$2201, -999), -999), _xlpm.ltv_prot, IFERROR(IF(_xlpm.matches, Engine!$AF$2:$AF$2201 / Engine!$R$2:$R$2201, 0), 0), _xlpm.combined, IF(_xlpm.ltv_prot >= INDEX(Selection_Assumptions[Values],3), INDEX(Selection_Assumptions[Values],1)*_xlpm.gr_lift + INDEX(Selection_Assumptions[Values],2)*_xlpm.gp_lift, -999), MATCH(MAX(_xlpm.combined), IF(_xlpm.matches, _xlpm.combined), 0) )} -> 81 | C8: {=_xlfn.LET( _xlpm.sku, $A8, _xlpm.matches, (Engine!$E$2:$E$2201=_xlpm.sku), _xlpm.gr_lift, IFERROR(IF(_xlpm.matches, Engine!$Z$2:$Z$2201 / Engine!$K$2:$K$2201, -999), -999), _xlpm.gp_lift, IFERROR(IF(_xlpm.matches, Engine!$AA$2:$AA$2201 / Engine!$L$2:$L$2201, -999), -999), _xlpm.ltv_prot, IFERROR(IF(_xlpm.matches, Engine!$AF$2:$AF$2201 / Engine!$R$2:$R$2201, 0), 0), _xlpm.combined, IF(_xlpm.ltv_prot >= INDEX(Selection_Assumptions[Values],3), INDEX(Selection_Assumptions[Values],1)*_xlpm.gr_lift + INDEX(Selection_Assumptions[Values],2)*_xlpm.gp_lift, -999), MAX(_xlpm.combined) )} -> 0.18771631 | D8: {=INDEX(Engine!$T$2:$T$2201, $B8)} -> 55.842395 | E8: {=IFERROR(INDEX(Engine!$Z$2:$Z$2201, $B8) / INDEX(Engine!$K$2:$K$2201, $B8), 0)} -> 0.028151567 | F8: {=IFERROR(INDEX(Engine!$AA$2:$AA$2201, $B8) / INDEX(Engine!$L$2:$L$2201, $B8), 0)} -> 0.13297062 | G8: {=IFERROR(INDEX(Engine!$AF$2:$AF$2201, $B8) / INDEX(Engine!$R$2:$R$2201, $B8), 0)} -> 0.4
A9: {=INDEX(Model_Input[SKU], ROW()-6)} -> SKU-1004 | B9: {=_xlfn.LET( _xlpm.sku, $A9, _xlpm.matches, (Engine!$E$2:$E$2201=_xlpm.sku), _xlpm.gr_lift, IFERROR(IF(_xlpm.matches, Engine!$Z$2:$Z$2201 / Engine!$K$2:$K$2201, -999), -999), _xlpm.gp_lift, IFERROR(IF(_xlpm.matches, Engine!$AA$2:$AA$2201 / Engine!$L$2:$L$2201, -999), -999), _xlpm.ltv_prot, IFERROR(IF(_xlpm.matches, Engine!$AF$2:$AF$2201 / Engine!$R$2:$R$2201, 0), 0), _xlpm.combined, IF(_xlpm.ltv_prot >= INDEX(Selection_Assumptions[Values],3), INDEX(Selection_Assumptions[Values],1)*_xlpm.gr_lift + INDEX(Selection_Assumptions[Values],2)*_xlpm.gp_lift, -999), MATCH(MAX(_xlpm.combined), IF(_xlpm.matches, _xlpm.combined), 0) )} -> 131 | C9: {=_xlfn.LET( _xlpm.sku, $A9, _xlpm.matches, (Engine!$E$2:$E$2201=_xlpm.sku), _xlpm.gr_lift, IFERROR(IF(_xlpm.matches, Engine!$Z$2:$Z$2201 / Engine!$K$2:$K$2201, -999), -999), _xlpm.gp_lift, IFERROR(IF(_xlpm.matches, Engine!$AA$2:$AA$2201 / Engine!$L$2:$L$2201, -999), -999), _xlpm.ltv_prot, IFERROR(IF(_xlpm.matches, Engine!$AF$2:$AF$2201 / Engine!$R$2:$R$2201, 0), 0), _xlpm.combined, IF(_xlpm.ltv_prot >= INDEX(Selection_Assumptions[Values],3), INDEX(Selection_Assumptions[Values],1)*_xlpm.gr_lift + INDEX(Selection_Assumptions[Values],2)*_xlpm.gp_lift, -999), MAX(_xlpm.combined) )} -> 0.14008396 | D9: {=INDEX(Engine!$T$2:$T$2201, $B9)} -> 19.551373 | E9: {=IFERROR(INDEX(Engine!$Z$2:$Z$2201, $B9) / INDEX(Engine!$K$2:$K$2201, $B9), 0)} -> 0.03629616 | F9: {=IFERROR(INDEX(Engine!$AA$2:$AA$2201, $B9) / INDEX(Engine!$L$2:$L$2201, $B9), 0)} -> 0.086489831 | G9: {=IFERROR(INDEX(Engine!$AF$2:$AF$2201, $B9) / INDEX(Engine!$R$2:$R$2201, $B9), 0)} -> 0.4
A10: {=INDEX(Model_Input[SKU], ROW()-6)} -> SKU-1005 | B10: {=_xlfn.LET( _xlpm.sku, $A10, _xlpm.matches, (Engine!$E$2:$E$2201=_xlpm.sku), _xlpm.gr_lift, IFERROR(IF(_xlpm.matches, Engine!$Z$2:$Z$2201 / Engine!$K$2:$K$2201, -999), -999), _xlpm.gp_lift, IFERROR(IF(_xlpm.matches, Engine!$AA$2:$AA$2201 / Engine!$L$2:$L$2201, -999), -999), _xlpm.ltv_prot, IFERROR(IF(_xlpm.matches, Engine!$AF$2:$AF$2201 / Engine!$R$2:$R$2201, 0), 0), _xlpm.combined, IF(_xlpm.ltv_prot >= INDEX(Selection_Assumptions[Values],3), INDEX(Selection_Assumptions[Values],1)*_xlpm.gr_lift + INDEX(Selection_Assumptions[Values],2)*_xlpm.gp_lift, -999), MATCH(MAX(_xlpm.combined), IF(_xlpm.matches, _xlpm.combined), 0) )} -> 151 | C10: {=_xlfn.LET( _xlpm.sku, $A10, _xlpm.matches, (Engine!$E$2:$E$2201=_xlpm.sku), _xlpm.gr_lift, IFERROR(IF(_xlpm.matches, Engine!$Z$2:$Z$2201 / Engine!$K$2:$K$2201, -999), -999), _xlpm.gp_lift, IFERROR(IF(_xlpm.matches, Engine!$AA$2:$AA$2201 / Engine!$L$2:$L$2201, -999), -999), _xlpm.ltv_prot, IFERROR(IF(_xlpm.matches, Engine!$AF$2:$AF$2201 / Engine!$R$2:$R$2201, 0), 0), _xlpm.combined, IF(_xlpm.ltv_prot >= INDEX(Selection_Assumptions[Values],3), INDEX(Selection_Assumptions[Values],1)*_xlpm.gr_lift + INDEX(Selection_Assumptions[Values],2)*_xlpm.gp_lift, -999), MAX(_xlpm.combined) )} -> 0 | D10: {=INDEX(Engine!$T$2:$T$2201, $B10)} -> 29.62 | E10: {=IFERROR(INDEX(Engine!$Z$2:$Z$2201, $B10) / INDEX(Engine!$K$2:$K$2201, $B10), 0)} -> 0 | F10: {=IFERROR(INDEX(Engine!$AA$2:$AA$2201, $B10) / INDEX(Engine!$L$2:$L$2201, $B10), 0)} -> 0 | G10: {=IFERROR(INDEX(Engine!$AF$2:$AF$2201, $B10) / INDEX(Engine!$R$2:$R$2201, $B10), 0)} -> 1
A11: {=INDEX(Model_Input[SKU], ROW()-6)} -> SKU-1006 | B11: {=_xlfn.LET( _xlpm.sku, $A11, _xlpm.matches, (Engine!$E$2:$E$2201=_xlpm.sku), _xlpm.gr_lift, IFERROR(IF(_xlpm.matches, Engine!$Z$2:$Z$2201 / Engine!$K$2:$K$2201, -999), -999), _xlpm.gp_lift, IFERROR(IF(_xlpm.matches, Engine!$AA$2:$AA$2201 / Engine!$L$2:$L$2201, -999), -999), _xlpm.ltv_prot, IFERROR(IF(_xlpm.matches, Engine!$AF$2:$AF$2201 / Engine!$R$2:$R$2201, 0), 0), _xlpm.combined, IF(_xlpm.ltv_prot >= INDEX(Selection_Assumptions[Values],3), INDEX(Selection_Assumptions[Values],1)*_xlpm.gr_lift + INDEX(Selection_Assumptions[Values],2)*_xlpm.gp_lift, -999), MATCH(MAX(_xlpm.combined), IF(_xlpm.matches, _xlpm.combined), 0) )} -> 231 | C11: {=_xlfn.LET( _xlpm.sku, $A11, _xlpm.matches, (Engine!$E$2:$E$2201=_xlpm.sku), _xlpm.gr_lift, IFERROR(IF(_xlpm.matches, Engine!$Z$2:$Z$2201 / Engine!$K$2:$K$2201, -999), -999), _xlpm.gp_lift, IFERROR(IF(_xlpm.matches, Engine!$AA$2:$AA$2201 / Engine!$L$2:$L$2201, -999), -999), _xlpm.ltv_prot, IFERROR(IF(_xlpm.matches, Engine!$AF$2:$AF$2201 / Engine!$R$2:$R$2201, 0), 0), _xlpm.combined, IF(_xlpm.ltv_prot >= INDEX(Selection_Assumptions[Values],3), INDEX(Selection_Assumptions[Values],1)*_xlpm.gr_lift + INDEX(Selection_Assumptions[Values],2)*_xlpm.gp_lift, -999), MAX(_xlpm.combined) )} -> 0.089473506 | D11: {=INDEX(Engine!$T$2:$T$2201, $B11)} -> 118.51611 | E11: {=IFERROR(INDEX(Engine!$Z$2:$Z$2201, $B11) / INDEX(Engine!$K$2:$K$2201, $B11), 0)} -> 0.027399113 | F11: {=IFERROR(INDEX(Engine!$AA$2:$AA$2201, $B11) / INDEX(Engine!$L$2:$L$2201, $B11), 0)} -> 0.051728661 | G11: {=IFERROR(INDEX(Engine!$AF$2:$AF$2201, $B11) / INDEX(Engine!$R$2:$R$2201, $B11), 0)} -> 0.4
A12: {=INDEX(Model_Input[SKU], ROW()-6)} -> SKU-1009 | B12: {=_xlfn.LET( _xlpm.sku, $A12, _xlpm.matches, (Engine!$E$2:$E$2201=_xlpm.sku), _xlpm.gr_lift, IFERROR(IF(_xlpm.matches, Engine!$Z$2:$Z$2201 / Engine!$K$2:$K$2201, -999), -999), _xlpm.gp_lift, IFERROR(IF(_xlpm.matches, Engine!$AA$2:$AA$2201 / Engine!$L$2:$L$2201, -999), -999), _xlpm.ltv_prot, IFERROR(IF(_xlpm.matches, Engine!$AF$2:$AF$2201 / Engine!$R$2:$R$2201, 0), 0), _xlpm.combined, IF(_xlpm.ltv_prot >= INDEX(Selection_Assumptions[Values],3), INDEX(Selection_Assumptions[Values],1)*_xlpm.gr_lift + INDEX(Selection_Assumptions[Values],2)*_xlpm.gp_lift, -999), MATCH(MAX(_xlpm.combined), IF(_xlpm.matches, _xlpm.combined), 0) )} -> 281 | C12: {=_xlfn.LET( _xlpm.sku, $A12, _xlpm.matches, (Engine!$E$2:$E$2201=_xlpm.sku), _xlpm.gr_lift, IFERROR(IF(_xlpm.matches, Engine!$Z$2:$Z$2201 / Engine!$K$2:$K$2201, -999), -999), _xlpm.gp_lift, IFERROR(IF(_xlpm.matches, Engine!$AA$2:$AA$2201 / Engine!$L$2:$L$2201, -999), -999), _xlpm.ltv_prot, IFERROR(IF(_xlpm.matches, Engine!$AF$2:$AF$2201 / Engine!$R$2:$R$2201, 0), 0), _xlpm.combined, IF(_xlpm.ltv_prot >= INDEX(Selection_Assumptions[Values],3), INDEX(Selection_Assumptions[Values],1)*_xlpm.gr_lift + INDEX(Selection_Assumptions[Values],2)*_xlpm.gp_lift, -999), MAX(_xlpm.combined) )} -> 0.22231295 | D12: {=INDEX(Engine!$T$2:$T$2201, $B12)} -> 197.38145 | E12: {=IFERROR(INDEX(Engine!$Z$2:$Z$2201, $B12) / INDEX(Engine!$K$2:$K$2201, $B12), 0)} -> 0.060875983 | F12: {=IFERROR(INDEX(Engine!$AA$2:$AA$2201, $B12) / INDEX(Engine!$L$2:$L$2201, $B12), 0)} -> 0.1345308 | G12: {=IFERROR(INDEX(Engine!$AF$2:$AF$2201, $B12) / INDEX(Engine!$R$2:$R$2201, $B12), 0)} -> 0.4
A13: {=INDEX(Model_Input[SKU], ROW()-6)} -> SKU-1010 | B13: {=_xlfn.LET( _xlpm.sku, $A13, _xlpm.matches, (Engine!$E$2:$E$2201=_xlpm.sku), _xlpm.gr_lift, IFERROR(IF(_xlpm.matches, Engine!$Z$2:$Z$2201 / Engine!$K$2:$K$2201, -999), -999), _xlpm.gp_lift, IFERROR(IF(_xlpm.matches, Engine!$AA$2:$AA$2201 / Engine!$L$2:$L$2201, -999), -999), _xlpm.ltv_prot, IFERROR(IF(_xlpm.matches, Engine!$AF$2:$AF$2201 / Engine!$R$2:$R$2201, 0), 0), _xlpm.combined, IF(_xlpm.ltv_prot >= INDEX(Selection_Assumptions[Values],3), INDEX(Selection_Assumptions[Values],1)*_xlpm.gr_lift + INDEX(Selection_Assumptions[Values],2)*_xlpm.gp_lift, -999), MATCH(MAX(_xlpm.combined), IF(_xlpm.matches, _xlpm.combined), 0) )} -> 331 | C13: {=_xlfn.LET( _xlpm.sku, $A13, _xlpm.matches, (Engine!$E$2:$E$2201=_xlpm.sku), _xlpm.gr_lift, IFERROR(IF(_xlpm.matches, Engine!$Z$2:$Z$2201 / Engine!$K$2:$K$2201, -999), -999), _xlpm.gp_lift, IFERROR(IF(_xlpm.matches, Engine!$AA$2:$AA$2201 / Engine!$L$2:$L$2201, -999), -999), _xlpm.ltv_prot, IFERROR(IF(_xlpm.matches, Engine!$AF$2:$AF$2201 / Engine!$R$2:$R$2201, 0), 0), _xlpm.combined, IF(_xlpm.ltv_prot >= INDEX(Selection_Assumptions[Values],3), INDEX(Selection_Assumptions[Values],1)*_xlpm.gr_lift + INDEX(Selection_Assumptions[Values],2)*_xlpm.gp_lift, -999), MAX(_xlpm.combined) )} -> 0.38670957 | D13: {=INDEX(Engine!$T$2:$T$2201, $B13)} -> 52.899021 | E13: {=IFERROR(INDEX(Engine!$Z$2:$Z$2201, $B13) / INDEX(Engine!$K$2:$K$2201, $B13), 0)} -> 0.082670011 | F13: {=IFERROR(INDEX(Engine!$AA$2:$AA$2201, $B13) / INDEX(Engine!$L$2:$L$2201, $B13), 0)} -> 0.2533663 | G13: {=IFERROR(INDEX(Engine!$AF$2:$AF$2201, $B13) / INDEX(Engine!$R$2:$R$2201, $B13), 0)} -> 0.4
A14: {=INDEX(Model_Input[SKU], ROW()-6)} -> SKU-1011 | B14: {=_xlfn.LET( _xlpm.sku, $A14, _xlpm.matches, (Engine!$E$2:$E$2201=_xlpm.sku), _xlpm.gr_lift, IFERROR(IF(_xlpm.matches, Engine!$Z$2:$Z$2201 / Engine!$K$2:$K$2201, -999), -999), _xlpm.gp_lift, IFERROR(IF(_xlpm.matches, Engine!$AA$2:$AA$2201 / Engine!$L$2:$L$2201, -999), -999), _xlpm.ltv_prot, IFERROR(IF(_xlpm.matches, Engine!$AF$2:$AF$2201 / Engine!$R$2:$R$2201, 0), 0), _xlpm.combined, IF(_xlpm.ltv_prot >= INDEX(Selection_Assumptions[Values],3), INDEX(Selection_Assumptions[Values],1)*_xlpm.gr_lift + INDEX(Selection_Assumptions[Values],2)*_xlpm.gp_lift, -999), MATCH(MAX(_xlpm.combined), IF(_xlpm.matches, _xlpm.combined), 0) )} -> 381 | C14: {=_xlfn.LET( _xlpm.sku, $A14, _xlpm.matches, (Engine!$E$2:$E$2201=_xlpm.sku), _xlpm.gr_lift, IFERROR(IF(_xlpm.matches, Engine!$Z$2:$Z$2201 / Engine!$K$2:$K$2201, -999), -999), _xlpm.gp_lift, IFERROR(IF(_xlpm.matches, Engine!$AA$2:$AA$2201 / Engine!$L$2:$L$2201, -999), -999), _xlpm.ltv_prot, IFERROR(IF(_xlpm.matches, Engine!$AF$2:$AF$2201 / Engine!$R$2:$R$2201, 0), 0), _xlpm.combined, IF(_xlpm.ltv_prot >= INDEX(Selection_Assumptions[Values],3), INDEX(Selection_Assumptions[Values],1)*_xlpm.gr_lift + INDEX(Selection_Assumptions[Values],2)*_xlpm.gp_lift, -999), MAX(_xlpm.combined) )} -> 0.21602349 | D14: {=INDEX(Engine!$T$2:$T$2201, $B14)} -> 71.933095 | E14: {=IFERROR(INDEX(Engine!$Z$2:$Z$2201, $B14) / INDEX(Engine!$K$2:$K$2201, $B14), 0)} -> 0.037161497 | F14: {=IFERROR(INDEX(Engine!$AA$2:$AA$2201, $B14) / INDEX(Engine!$L$2:$L$2201, $B14), 0)} -> 0.14905166 | G14: {=IFERROR(INDEX(Engine!$AF$2:$AF$2201, $B14) / INDEX(Engine!$R$2:$R$2201, $B14), 0)} -> 0.4
A15: {=INDEX(Model_Input[SKU], ROW()-6)} -> SKU-1012 | B15: {=_xlfn.LET( _xlpm.sku, $A15, _xlpm.matches, (Engine!$E$2:$E$2201=_xlpm.sku), _xlpm.gr_lift, IFERROR(IF(_xlpm.matches, Engine!$Z$2:$Z$2201 / Engine!$K$2:$K$2201, -999), -999), _xlpm.gp_lift, IFERROR(IF(_xlpm.matches, Engine!$AA$2:$AA$2201 / Engine!$L$2:$L$2201, -999), -999), _xlpm.ltv_prot, IFERROR(IF(_xlpm.matches, Engine!$AF$2:$AF$2201 / Engine!$R$2:$R$2201, 0), 0), _xlpm.combined, IF(_xlpm.ltv_prot >= INDEX(Selection_Assumptions[Values],3), INDEX(Selection_Assumptions[Values],1)*_xlpm.gr_lift + INDEX(Selection_Assumptions[Values],2)*_xlpm.gp_lift, -999), MATCH(MAX(_xlpm.combined), IF(_xlpm.matches, _xlpm.combined), 0) )} -> 401 | C15: {=_xlfn.LET( _xlpm.sku, $A15, _xlpm.matches, (Engine!$E$2:$E$2201=_xlpm.sku), _xlpm.gr_lift, IFERROR(IF(_xlpm.matches, Engine!$Z$2:$Z$2201 / Engine!$K$2:$K$2201, -999), -999), _xlpm.gp_lift, IFERROR(IF(_xlpm.matches, Engine!$AA$2:$AA$2201 / Engine!$L$2:$L$2201, -999), -999), _xlpm.ltv_prot, IFERROR(IF(_xlpm.matches, Engine!$AF$2:$AF$2201 / Engine!$R$2:$R$2201, 0), 0), _xlpm.combined, IF(_xlpm.ltv_prot >= INDEX(Selection_Assumptions[Values],3), INDEX(Selection_Assumptions[Values],1)*_xlpm.gr_lift + INDEX(Selection_Assumptions[Values],2)*_xlpm.gp_lift, -999), MAX(_xlpm.combined) )} -> 0 | D15: {=INDEX(Engine!$T$2:$T$2201, $B15)} -> 20.37 | E15: {=IFERROR(INDEX(Engine!$Z$2:$Z$2201, $B15) / INDEX(Engine!$K$2:$K$2201, $B15), 0)} -> 0 | F15: {=IFERROR(INDEX(Engine!$AA$2:$AA$2201, $B15) / INDEX(Engine!$L$2:$L$2201, $B15), 0)} -> 0 | G15: {=IFERROR(INDEX(Engine!$AF$2:$AF$2201, $B15) / INDEX(Engine!$R$2:$R$2201, $B15), 0)} -> 1
