Workbook

Sheet Final Candidate Output
A1: Criteria for selection: Gross Profit Lift % > 5% LTV Protection Ratio >40% | E1: AVERAGE GR LIFT % | F1: =AVERAGE($AH$10:$AH$33) -> 0.049460573
E2: AERAGE GP LIFT % | F2: =AVERAGE($AN$10:$AN$33) -> 0.12326403
E3: AVERAGE PRICE LIFT % | F3: =AVERAGE($AC$10:$AC$33) -> 0.08875811
A9: SKU | B9: Product Name | C9: Category | D9: Recommendation | E9: Current Price | F9: Current Cost Per Unit | G9: Current Volume | H9: Current Gross Revenue | I9: Current COGS | J9: Current Gross Profit | K9: Current Gross Profit Margin % | L9: V1 Suggested Price | M9: V1 Difference $ | N9: V1 Difference % | O9: V1 Gross Revenue Impact | P9: V1 Gross Profit Impact $ | Q9: Total Buyers | R9: Average Churn Score | S9: Average Projected Churn Rate | T9: Total Buyer LTV | U9: Total LTV at Risk | V9: % Critical | W9: % High | X9: % Medium | Y9: %Low | Z9: Dominant Tier | AA9: Adjusted Price | AB9: Adjusted Difference $ | AC9: Adjusted Difference % | AD9: Adjusted Volume Change % | AE9: Adjusted Volume | AF9: Adjusted Projected Gross Revenue | AG9: Adjusted Gross Revenue Impact | AH9: Adjusted Gross Revenue Lift | AI9: Adjusted COGS | AJ9: Adjusted COGS Impact | AK9: Adjusted COGS Lift | AL9: Adjusted Gross Profit | AM9: Projected Gross Profit Impact $ | AN9: Projected Gross Profit Lift % | AO9: Projected Gross Profit Margin % | AP9: Project Gross Profit Margin Impact % | AQ9: Projected Gross Profit Margin Lift | AR9: LTV Protected | AS9: LTV Sacrificed | AT9: LTV Protection-Adjusted Risk Ratio
A10: {=_xlfn._xlws.FILTER(_xlfn.ANCHORARRAY('Monte Carlo IO (4)'!$A$12),('Monte Carlo IO (4)'!$AO$12:$AO$53>0.05),('Monte Carlo IO (4)'!$AU$12:$AU$53>0.4))} -> SKU-1000 | B10: {=_xlfn.XLOOKUP($A10,_xlfn.ANCHORARRAY('Monte Carlo IO (4)'!$A$12), 'Monte Carlo IO (4)'!$B$12:$D$53,,0)} -> Wireless Earbuds | C10: Electronics | D10: Raise | E10: {=_xlfn.XLOOKUP($A10,_xlfn.ANCHORARRAY('Monte Carlo IO (4)'!$A$12), 'Monte Carlo IO (4)'!$F$12:$L$53)} -> 76.53 | F10: 52.96 | G10: 24 | H10: 1836.72 | I10: 1271.04 | J10: 565.68 | K10: 0.3079838 | L10: {=_xlfn.XLOOKUP($A10,_xlfn.ANCHORARRAY('Monte Carlo IO (4)'!$A$12), 'Monte Carlo IO (4)'!$M$12:$AU$53)} -> 80.606323 | M10: 4.0763228 | N10: 0.053264378 | O10: 17.225425 | P10: 70.185425 | Q10: 10 | R10: 70.505262 | S10: 0.3181247 | T10: 3841.99 | U10: 1112.0932 | V10: 0.5 | W10: 0.3 | X10: 0.2 | Y10: 0 | Z10: Critical | AA10: 78.975794 | AB10: 2.4457937 | AC10: 0.031958627 | AD10: -0.012783451 | AE10: 24.012783 | AF10: 1871.1891 | AG10: 34.469053 | AH10: 0.018766635 | AI10: 1271.717 | AJ10: 0.67701155 | AK10: 0.00053264378 | AL10: 616.39733 | AM10: 50.71733 | AN10: 0.08965728 | AO10: 0.32941478 | AP10: 0.021430983 | AQ10: 0.021430983 | AR10: 358.09401 | AS10: 537.14101 | AT10: 0.66666667
A11: SKU-1001 | B11: {=_xlfn.XLOOKUP($A11,_xlfn.ANCHORARRAY('Monte Carlo IO (4)'!$A$12), 'Monte Carlo IO (4)'!$B$12:$D$53,,0)} -> Bluetooth Speaker | C11: Electronics | D11: Raise | E11: {=_xlfn.XLOOKUP($A11,_xlfn.ANCHORARRAY('Monte Carlo IO (4)'!$A$12), 'Monte Carlo IO (4)'!$F$12:$L$53)} -> 53.26 | F11: 36.64 | G11: 21 | H11: 1118.46 | I11: 769.44 | J11: 349.02 | K11: 0.31205407 | L11: {=_xlfn.XLOOKUP($A11,_xlfn.ANCHORARRAY('Monte Carlo IO (4)'!$A$12), 'Monte Carlo IO (4)'!$M$12:$AU$53)} -> 57.563992 | M11: 4.3039918 | N11: 0.080810961 | O11: 32.819836 | P11: 69.459836 | Q11: 9 | R11: 66.806056 | S11: 0.26336465 | T11: 5045.98 | U11: 1487.03 | V11: 0.33333333 | W11: 0.44444444 | X11: 0.22222222 | Y11: 0 | Z11: High | AA11: 55.842395 | AB11: 2.5823951 | AC11: 0.048486577 | AD11: -0.019394631 | AE11: 21.019395 | AF11: 1149.9464 | AG11: 31.486401 | AH11: 0.028151567 | AI11: 1113.1871 | AJ11: 343.74714 | AK11: 0.44674977 | AL11: 395.42941 | AM11: 46.409406 | AN11: 0.13297062 | AO11: 0.34386768 | AP11: 0.03181361 | AQ11: 0.03181361 | AR11: 449.41351 | AS11: 674.12027 | AT11: 0.66666667
A12: SKU-1004 | B12: {=_xlfn.XLOOKUP($A12,_xlfn.ANCHORARRAY('Monte Carlo IO (4)'!$A$12), 'Monte Carlo IO (4)'!$B$12:$D$53,,0)} -> USB-C Hub | C12: Electronics | D12: Hold | E12: {=_xlfn.XLOOKUP($A12,_xlfn.ANCHORARRAY('Monte Carlo IO (4)'!$A$12), 'Monte Carlo IO (4)'!$F$12:$L$53)} -> 18.39 | F12: 8.26 | G12: 17 | H12: 312.63 | I12: 140.42 | J12: 172.21 | K12: 0.55084285 | L12: {=_xlfn.XLOOKUP($A12,_xlfn.ANCHORARRAY('Monte Carlo IO (4)'!$A$12), 'Monte Carlo IO (4)'!$M$12:$AU$53)} -> 20.325622 | M12: 1.9356217 | N12: 0.10525403 | O12: 12.579946 | P12: 20.839946 | Q12: 9 | R12: 68.467577 | S12: 0.2519532 | T12: 6058.75 | U12: 1216.0707 | V12: 0.55555556 | W12: 0.11111111 | X12: 0.33333333 | Y12: 0 | Z12: Critical | AA12: 19.551373 | AB12: 1.161373 | AC12: 0.063152419 | AD12: -0.025260968 | AE12: 17.025261 | AF12: 323.97727 | AG12: 11.347269 | AH12: 0.03629616 | AI12: 901.65782 | AJ12: 761.23782 | AK12: 5.4211496 | AL12: 187.10441 | AM12: 14.894414 | AN12: 0.086489831 | AO12: 0.57752328 | AP12: 0.026680427 | AQ12: 0.026680427 | AR12: 375.63072 | AS12: 563.44608 | AT12: 0.66666667
A13: SKU-1006 | B13: {=_xlfn.XLOOKUP($A13,_xlfn.ANCHORARRAY('Monte Carlo IO (4)'!$A$12), 'Monte Carlo IO (4)'!$B$12:$D$53,,0)} -> Mechanical Keyboard | C13: Electronics | D13: Hold | E13: {=_xlfn.XLOOKUP($A13,_xlfn.ANCHORARRAY('Monte Carlo IO (4)'!$A$12), 'Monte Carlo IO (4)'!$F$12:$L$53)} -> 113.18 | F13: 39.01 | G13: 24 | H13: 2716.32 | I13: 936.24 | J13: 1780.08 | K13: 0.6553278 | L13: {=_xlfn.XLOOKUP($A13,_xlfn.ANCHORARRAY('Monte Carlo IO (4)'!$A$12), 'Monte Carlo IO (4)'!$M$12:$AU$53)} -> 122.07351 | M13: 8.8935122 | N13: 0.078578479 | O13: 91.370781 | P13: 130.38078 | Q13: 10 | R13: 63.379342 | S13: 0.1953265 | T13: 8331.72 | U13: 1378.1368 | V13: 0.4 | W13: 0.3 | X13: 0.2 | Y13: 0.1 | Z13: Critical | AA13: 118.51611 | AB13: 5.3361073 | AC13: 0.047147087 | AD13: -0.018858835 | AE13: 24.018859 | AF13: 2790.7448 | AG13: 74.424759 | AH13: 0.027399113 | AI13: 1272.0388 | AJ13: 335.79876 | AK13: 0.3586674 | AL13: 1872.1612 | AM13: 92.081155 | AN13: 0.051728661 | AO13: 0.67084643 | AP13: 0.015518632 | AQ13: 0.015518632 | AR13: 396.9034 | AS13: 595.3551 | AT13: 0.66666667
A14: SKU-1009 | B14: {=_xlfn.XLOOKUP($A14,_xlfn.ANCHORARRAY('Monte Carlo IO (4)'!$A$12), 'Monte Carlo IO (4)'!$B$12:$D$53,,0)} -> Phone Stand | C14: Electronics | D14: Raise | E14: {=_xlfn.XLOOKUP($A14,_xlfn.ANCHORARRAY('Monte Carlo IO (4)'!$A$12), 'Monte Carlo IO (4)'!$F$12:$L$53)} -> 177.91 | F14: 73.49 | G14: 36 | H14: 6404.76 | I14: 2645.64 | J14: 3759.12 | K14: 0.58692597 | L14: {=_xlfn.XLOOKUP($A14,_xlfn.ANCHORARRAY('Monte Carlo IO (4)'!$A$12), 'Monte Carlo IO (4)'!$M$12:$AU$53)} -> 210.36242 | M14: 32.452421 | N14: 0.1824092 | O14: 2118.3199 | P14: 2338.7899 | Q14: 12 | R14: 72.583716 | S14: 0.2476082 | T14: 9553.98 | U14: 1987.1738 | V14: 0.58333333 | W14: 0.33333333 | X14: 0.083333333 | Y14: 0 | Z14: Critical | AA14: 197.38145 | AB14: 19.471452 | AC14: 0.10944552 | AD14: -0.043778208 | AE14: 36.043778 | AF14: 6794.6561 | AG14: 389.89606 | AH14: 0.060875983 | AI14: 1908.8785 | AJ14: -736.76151 | AK14: -0.27848139 | AL14: 4264.8374 | AM14: 505.71744 | AN14: 0.1345308 | AO14: 0.62767525 | AP14: 0.040749276 | AQ14: 0.040749276 | AR14: 688.8869 | AS14: 1033.3304 | AT14: 0.66666667
A15: SKU-1010 | B15: {=_xlfn.XLOOKUP($A15,_xlfn.ANCHORARRAY('Monte Carlo IO (4)'!$A$12), 'Monte Carlo IO (4)'!$B$12:$D$53,,0)} -> Slim Fit Jeans | C15: Apparel | D15: Raise | E15: {=_xlfn.XLOOKUP($A15,_xlfn.ANCHORARRAY('Monte Carlo IO (4)'!$A$12), 'Monte Carlo IO (4)'!$F$12:$L$53)} -> 45.86 | F15: 24.87 | G15: 42 | H15: 1926.12 | I15: 1044.54 | J15: 881.58 | K15: 0.45769734 | L15: {=_xlfn.XLOOKUP($A15,_xlfn.ANCHORARRAY('Monte Carlo IO (4)'!$A$12), 'Monte Carlo IO (4)'!$M$12:$AU$53)} -> 57.591702 | M15: 11.731702 | N15: 0.25581556 | O15: 713.86466 | P15: 813.34466 | Q15: 17 | R15: 81.368043 | S15: 0.36473224 | T15: 5696.89 | U15: 1838.4437 | V15: 0.70588235 | W15: 0.23529412 | X15: 0.058823529 | Y15: 0 | Z15: Critical | AA15: 52.899021 | AB15: 7.0390209 | AC15: 0.15348934 | AD15: -0.061395734 | AE15: 42.061396 | AF15: 2085.3524 | AG15: 159.23236 | AH15: 0.082670011 | AI15: 2227.5715 | AJ15: 1183.0315 | AK15: 1.1325861 | AL15: 1104.9427 | AM15: 223.36266 | AN15: 0.2533663 | AO15: 0.52985897 | AP15: 0.072161634 | AQ15: 0.072161634 | AR15: 666.16547 | AS15: 999.2482 | AT15: 0.66666667
A16: SKU-1011 | B16: {=_xlfn.XLOOKUP($A16,_xlfn.ANCHORARRAY('Monte Carlo IO (4)'!$A$12), 'Monte Carlo IO (4)'!$B$12:$D$53,,0)} -> Graphic Tee | C16: Apparel | D16: Raise | E16: {=_xlfn.XLOOKUP($A16,_xlfn.ANCHORARRAY('Monte Carlo IO (4)'!$A$12), 'Monte Carlo IO (4)'!$F$12:$L$53)} -> 67.56 | F16: 43.21 | G16: 22 | H16: 1486.32 | I16: 950.62 | J16: 535.7 | K16: 0.36042037 | L16: {=_xlfn.XLOOKUP($A16,_xlfn.ANCHORARRAY('Monte Carlo IO (4)'!$A$12), 'Monte Carlo IO (4)'!$M$12:$AU$53)} -> 74.848492 | M16: 7.2884925 | N16: 0.10788177 | O16: 85.498342 | P16: 128.70834 | Q16: 10 | R16: 66.15144 | S16: 0.25273448 | T16: 5893.09 | U16: 1511.5432 | V16: 0.4 | W16: 0.2 | X16: 0.4 | Y16: 0 | Z16: Critical | AA16: 71.933095 | AB16: 4.3730955 | AC16: 0.064729063 | AD16: -0.025891625 | AE16: 22.025892 | AF16: 1541.5539 | AG16: 55.233876 | AH16: 0.037161497 | AI16: 1166.4912 | AJ16: 215.87122 | AK16: 0.22708466 | AL16: 615.54697 | AM16: 79.846973 | AN16: 0.14905166 | AO16: 0.39930293 | AP16: 0.038882559 | AQ16: 0.038882559 | AR16: 429.27827 | AS16: 643.91741 | AT16: 0.66666667
A17: SKU-1014 | B17: {=_xlfn.XLOOKUP($A17,_xlfn.ANCHORARRAY('Monte Carlo IO (4)'!$A$12), 'Monte Carlo IO (4)'!$B$12:$D$53,,0)} -> Wool Sweater | C17: Apparel | D17: Raise | E17: {=_xlfn.XLOOKUP($A17,_xlfn.ANCHORARRAY('Monte Carlo IO (4)'!$A$12), 'Monte Carlo IO (4)'!$F$12:$L$53)} -> 143.8 | F17: 62.15 | G17: 29 | H17: 4170.2 | I17: 1802.35 | J17: 2367.85 | K17: 0.5678025 | L17: {=_xlfn.XLOOKUP($A17,_xlfn.ANCHORARRAY('Monte Carlo IO (4)'!$A$12), 'Monte Carlo IO (4)'!$M$12:$AU$53)} -> 176.09453 | M17: 32.294528 | N17: 0.22457947 | O17: 408.25774 | P17: 594.70774 | Q17: 10 | R17: 75.767552 | S17: 0.28614482 | T17: 4045.53 | U17: 1207.1798 | V17: 0.5 | W17: 0.5 | X17: 0 | Y17: 0 | Z17: Critical | AA17: 163.17672 | AB17: 19.376717 | AC17: 0.13474768 | AD17: -0.053899074 | AE17: 29.053899 | AF17: 4477.0677 | AG17: 306.86765 | AH17: 0.073585836 | AI17: 1538.6945 | AJ17: -263.65551 | AK17: -0.1462843 | AL17: 2771.8626 | AM17: 404.01265 | AN17: 0.17062426 | AO17: 0.61912458 | AP17: 0.051322081 | AQ17: 0.051322081 | AR17: 422.51294 | AS17: 633.76941 | AT17: 0.66666667
A18: SKU-1019 | B18: {=_xlfn.XLOOKUP($A18,_xlfn.ANCHORARRAY('Monte Carlo IO (4)'!$A$12), 'Monte Carlo IO (4)'!$B$12:$D$53,,0)} -> Canvas Tote Bag | C18: Apparel | D18: Raise | E18: {=_xlfn.XLOOKUP($A18,_xlfn.ANCHORARRAY('Monte Carlo IO (4)'!$A$12), 'Monte Carlo IO (4)'!$F$12:$L$53)} -> 160.35 | F18: 72.47 | G18: 36 | H18: 5772.6 | I18: 2608.92 | J18: 3163.68 | K18: 0.54805114 | L18: {=_xlfn.XLOOKUP($A18,_xlfn.ANCHORARRAY('Monte Carlo IO (4)'!$A$12), 'Monte Carlo IO (4)'!$M$12:$AU$53)} -> 182.28731 | M18: 21.937309 | N18: 0.13680891 | O18: 425.16851 | P18: 570.10851 | Q18: 12 | R18: 69.769541 | S18: 0.28227914 | T18: 5455.85 | U18: 1437.421 | V18: 0.41666667 | W18: 0.41666667 | X18: 0.16666667 | Y18: 0 | Z18: Critical | AA18: 173.51239 | AB18: 13.162385 | AC18: 0.082085347 | AD18: -0.032834139 | AE18: 36.032834 | AF18: 6041.3492 | AG18: 268.7492 | AH18: 0.046556007 | AI18: 1908.2989 | AJ18: -700.6211 | AK18: -0.26854833 | AL18: 3518.0908 | AM18: 354.41085 | AN18: 0.11202487 | AO18: 0.58233529 | AP18: 0.034284153 | AQ18: 0.034284153 | AR18: 457.57901 | AS18: 686.36852 | AT18: 0.66666667
A19: SKU-1021 | B19: {=_xlfn.XLOOKUP($A19,_xlfn.ANCHORARRAY('Monte Carlo IO (4)'!$A$12), 'Monte Carlo IO (4)'!$B$12:$D$53,,0)} -> Air Fryer | C19: Home & Kitchen | D19: Raise | E19: {=_xlfn.XLOOKUP($A19,_xlfn.ANCHORARRAY('Monte Carlo IO (4)'!$A$12), 'Monte Carlo IO (4)'!$F$12:$L$53)} -> 98.51 | F19: 55.17 | G19: 34 | H19: 3349.34 | I19: 1875.78 | J19: 1473.56 | K19: 0.43995533 | L19: {=_xlfn.XLOOKUP($A19,_xlfn.ANCHORARRAY('Monte Carlo IO (4)'!$A$12), 'Monte Carlo IO (4)'!$M$12:$AU$53)} -> 115.63152 | M19: 17.12152 | N19: 0.17380489 | O19: 350.86864 | P19: 461.20864 | Q19: 13 | R19: 67.896641 | S19: 0.2190319 | T19: 7864.87 | U19: 1821.0804 | V19: 0.46153846 | W19: 0.38461538 | X19: 0.15384615 | Y19: 0 | Z19: Critical | AA19: 108.78291 | AB19: 10.272912 | AC19: 0.10428294 | AD19: -0.041713175 | AE19: 34.041713 | AF19: 3544.3379 | AG19: 194.99787 | AH19: 0.05821979 | AI19: 1802.8491 | AJ19: -72.93087 | AK19: -0.03888029 | AL19: 1746.8026 | AM19: 273.24261 | AN19: 0.18543026 | AO19: 0.49284314 | AP19: 0.052887807 | AQ19: 0.052887807 | AR19: 591.15071 | AS19: 886.72606 | AT19: 0.66666667
A20: SKU-1026 | B20: {=_xlfn.XLOOKUP($A20,_xlfn.ANCHORARRAY('Monte Carlo IO (4)'!$A$12), 'Monte Carlo IO (4)'!$B$12:$D$53,,0)} -> Dish Rack | C20: Home & Kitchen | D20: Raise | E20: {=_xlfn.XLOOKUP($A20,_xlfn.ANCHORARRAY('Monte Carlo IO (4)'!$A$12), 'Monte Carlo IO (4)'!$F$12:$L$53)} -> 106.06 | F20: 33.42 | G20: 39 | H20: 4136.34 | I20: 1303.38 | J20: 2832.96 | K20: 0.68489534 | L20: {=_xlfn.XLOOKUP($A20,_xlfn.ANCHORARRAY('Monte Carlo IO (4)'!$A$12), 'Monte Carlo IO (4)'!$M$12:$AU$53)} -> 125.95982 | M20: 19.899821 | N20: 0.18762795 | O20: 398.21354 | P20: 498.47354 | Q20: 12 | R20: 83.640694 | S20: 0.39945616 | T20: 3203.34 | U20: 1061.3752 | V20: 0.75 | W20: 0.16666667 | X20: 0.083333333 | Y20: 0 | Z20: Critical | AA20: 117.99989 | AB20: 11.939892 | AC20: 0.11257677 | AD20: -0.045030708 | AE20: 39.045031 | AF20: 4394.7647 | AG20: 258.42467 | AH20: 0.062476651 | AI20: 2067.8248 | AJ20: 764.44483 | AK20: 0.58650956 | AL20: 3150.0768 | AM20: 317.1168 | AN20: 0.11193832 | AO20: 0.7167794 | AP20: 0.03188406 | AQ20: 0.03188406 | AR20: 385.63297 | AS20: 578.44946 | AT20: 0.66666667
A21: SKU-1027 | B21: {=_xlfn.XLOOKUP($A21,_xlfn.ANCHORARRAY('Monte Carlo IO (4)'!$A$12), 'Monte Carlo IO (4)'!$B$12:$D$53,,0)} -> Storage Bins | C21: Home & Kitchen | D21: Raise | E21: {=_xlfn.XLOOKUP($A21,_xlfn.ANCHORARRAY('Monte Carlo IO (4)'!$A$12), 'Monte Carlo IO (4)'!$F$12:$L$53)} -> 34.48 | F21: 19.24 | G21: 19 | H21: 655.12 | I21: 365.56 | J21: 289.56 | K21: 0.44199536 | L21: {=_xlfn.XLOOKUP($A21,_xlfn.ANCHORARRAY('Monte Carlo IO (4)'!$A$12), 'Monte Carlo IO (4)'!$M$12:$AU$53)} -> 36.908162 | M21: 2.4281619 | N21: 0.070422329 | O21: 9.2269146 | P21: 28.466915 | Q21: 7 | R21: 73.558325 | S21: 0.22727842 | T21: 2703.13 | U21: 804.52718 | V21: 0.57142857 | W21: 0.14285714 | X21: 0.28571429 | Y21: 0 | Z21: Critical | AA21: 35.936897 | AB21: 1.4568972 | AC21: 0.042253398 | AD21: -0.016901359 | AE21: 19.016901 | AF21: 671.26078 | AG21: 16.14078 | AH21: 0.024637899 | AI21: 1007.1351 | AJ21: 641.5751 | AK21: 1.7550473 | AL21: 311.87924 | AM21: 22.319241 | AN21: 0.077079849 | AO21: 0.46461711 | AP21: 0.022621746 | AQ21: 0.022621746 | AR21: 255.15005 | AS21: 382.72507 | AT21: 0.66666667
A22: SKU-1029 | B22: {=_xlfn.XLOOKUP($A22,_xlfn.ANCHORARRAY('Monte Carlo IO (4)'!$A$12), 'Monte Carlo IO (4)'!$B$12:$D$53,,0)} -> Scented Candle | C22: Home & Kitchen | D22: Raise | E22: {=_xlfn.XLOOKUP($A22,_xlfn.ANCHORARRAY('Monte Carlo IO (4)'!$A$12), 'Monte Carlo IO (4)'!$F$12:$L$53)} -> 148.11 | F22: 69.64 | G22: 27 | H22: 3998.97 | I22: 1880.28 | J22: 2118.69 | K22: 0.52980893 | L22: {=_xlfn.XLOOKUP($A22,_xlfn.ANCHORARRAY('Monte Carlo IO (4)'!$A$12), 'Monte Carlo IO (4)'!$M$12:$AU$53)} -> 164.85972 | M22: 16.749716 | N22: 0.1130897 | O22: 917.56261 | P22: 987.20261 | Q22: 12 | R22: 67.01174 | S22: 0.25894827 | T22: 7071.97 | U22: 1774.9244 | V22: 0.5 | W22: 0.083333333 | X22: 0.41666667 | Y22: 0 | Z22: Critical | AA22: 157.82484 | AB22: 9.7148351 | AC22: 0.065592027 | AD22: -0.026236811 | AE22: 27.026237 | AF22: 4149.4684 | AG22: 150.4984 | AH22: 0.037634291 | AI22: 1431.3095 | AJ22: -448.9705 | AK22: -0.23877853 | AL22: 2318.5209 | AM22: 199.83095 | AN22: 0.094318164 | AO22: 0.55875132 | AP22: 0.028942395 | AQ22: 0.028942395 | AR22: 543.57058 | AS22: 750.64509 | AT22: 0.72413793
... A33: SKU-1049 | B33: {=_xlfn.XLOOKUP($A33,_xlfn.ANCHORARRAY('Monte Carlo IO (4)'!$A$12), 'Monte Carlo IO (4)'!$B$12:$D$53,,0)} -> Protein Shaker | C33: Sports & Outdoors | D33: Raise | E33: {=_xlfn.XLOOKUP($A33,_xlfn.ANCHORARRAY('Monte Carlo IO (4)'!$A$12), 'Monte Carlo IO (4)'!$F$12:$L$53)} -> 99.75 | F33: 38.13 | G33: 34 | H33: 3391.5 | I33: 1296.42 | J33: 2095.08 | K33: 0.61774436 | L33: {=_xlfn.XLOOKUP($A33,_xlfn.ANCHORARRAY('Monte Carlo IO (4)'!$A$12), 'Monte Carlo IO (4)'!$M$12:$AU$53)} -> 110.43409 | M33: 10.684091 | N33: 0.10710868 | O33: 597.24501 | P33: 635.37501 | Q33: 13 | R33: 62.63275 | S33: 0.23171703 | T33: 6043.77 | U33: 1533.9834 | V33: 0.30769231 | W33: 0.53846154 | X33: 0.15384615 | Y33: 0 | Z33: High | AA33: 106.16045 | AB33: 6.4104547 | AC33: 0.06426521 | AD33: -0.025706084 | AE33: 34.025706 | AF33: 3516.6705 | AG33: 125.1705 | AH33: 0.036907119 | AI33: 1802.0014 | AJ33: 505.58139 | AK33: 0.38998272 | AL33: 2253.5764 | AM33: 158.49638 | AN33: 0.075651706 | AO33: 0.64082671 | AP33: 0.023082347 | AQ33: 0.023082347 | AR33: 474.35487 | AS33: 711.53231 | AT33: 0.66666667

Sheet Competitive Analysis (Step 1)
A1: COMPETITIVE MODEL ASSUMPTIONS | B1: Values
A2: Tolerance Band | B2: 0.1
A3: Tie Break Rule | B3: Raise
A4: Raise Elasticity | B4: -0.4
A5: Reduce Elasticity | B5: -0.8
A6: Raise Premium | B6: 0.05
A7: Rating Price Adjustment | B7: $2 per 0.1 delta
A9: {=_4_competitor_pricing_[#All]} -> SKU | B9: Product Name | C9: Competitor | D9: Competitor Price | E9: Comp Rating | F9: Comp Review Count | G9: Observation Date | H9: Average Competitor Price | I9: Price Delta | J9: Category | K9: Our Price | L9: Our Cost | M9: Our Gross Margin (%) | N9: Our Rating | O9: Our Review Count | P9: Our Stock Units | Q9: Total Units Sold | R9: Gross Revenue | S9: Total COGS | T9: Total Gross Profit | U9: Discounts Applied $ | V9: Total Revenue Less Discounts | W9: Total Net Profit $ | X9: Net Profit Margin % | Y9: Order Count | Z9: Avg Discount % | AA9: % Discount Sensitive (High) | AB9: % Loyal High-Value Buyers | AC9: %At-Risk Churner | AD9: %Dormant | AE9: % Deal Hunter Buyers | AF9: Avg Days Since Last Order | AG9: Return Rate % | AH9: Cancellation Rate % | AI9: Signal
A10: SKU-1000 | B10: Wireless Earbuds | C10: RivalMart | D10: 63.06 | E10: 4.3 | F10: 1109 | G10: 45321 | H10: {=AVERAGEIF($A10:$A209, $A10:$A209, $D10:$D209)} -> 71.835 | I10: =($K10 - $D10) / $D10 -> 0.21360609 | J10: {=_xlfn.XLOOKUP($A10:$A209, _1_product_catalog_pricing[SKU], _1_product_catalog_pricing[Category], , 0)} -> Electronics | K10: {=_xlfn.XLOOKUP($A10:$A209, _1_product_catalog_pricing[SKU], _1_product_catalog_pricing[Retail Price ($)], , 0)} -> 76.53 | L10: {=_xlfn.XLOOKUP($A10:$A209, _1_product_catalog_pricing[SKU], _1_product_catalog_pricing[Cost Price ($)], ,0)} -> 52.96 | M10: {=(_xlfn.ANCHORARRAY($K10)-_xlfn.ANCHORARRAY($L10))/_xlfn.ANCHORARRAY($K10)} -> 0.3079838 | N10: {=_xlfn.XLOOKUP($A10:$A209, _1_product_catalog_pricing[SKU], _1_product_catalog_pricing[Rating (1-5)],,0)} -> 4.5 | O10: {=_xlfn.XLOOKUP($A10:$A209, _1_product_catalog_pricing[SKU], _1_product_catalog_pricing[Review Count],,0)} -> 2781 | P10: {=_xlfn.XLOOKUP($A10:$A209, _1_product_catalog_pricing[SKU], _1_product_catalog_pricing[Stock Units],,0)} -> 71 | Q10: {=SUMIFS(_2_sales_transactions[Quantity], _2_sales_transactions[SKU], 'Competitive Analysis (Step 1)'!$A10:$A209, _2_sales_transactions[Order Status], "Completed")} -> 24 | R10: {=SUMIFS(Transactions_and_Customer_Information_Joined[Gross Revenue], Transactions_and_Customer_Information_Joined[SKU], 'Competitive Analysis (Step 1)'!A10:A209, Transactions_and_Customer_Information_Joined[Order Status], "Completed")} -> 1836.72 | S10: {=SUMIFS(_2_sales_transactions[COGS ($)], _2_sales_transactions[SKU], 'Competitive Analysis (Step 1)'!$A10:$A209, _2_sales_transactions[Order Status], "Completed")} -> 1271.04 | T10: {=_xlfn.ANCHORARRAY($R10)-_xlfn.ANCHORARRAY($S10)} -> 565.68 | U10: {=SUMIFS(Transactions_and_Customer_Information_Joined[Discount Amount ($)], Transactions_and_Customer_Information_Joined[SKU], 'Competitive Analysis (Step 1)'!A10:A209, Transactions_and_Customer_Information_Joined[Order Status], "Completed")} -> 91.83 | V10: {=SUMIFS(_2_sales_transactions[Revenue Less Discount ($)], _2_sales_transactions[SKU], 'Competitive Analysis (Step 1)'!$A10:$A209, _2_sales_transactions[Order Status], "Completed")} -> 1744.89 | W10: =SUMIFS(Transactions_and_Customer_Information_Joined[Gross Profit ($)], Transactions_and_Customer_Information_Joined[SKU], 'Competitive Analysis (Step 1)'!$A10, Transactions_and_Customer_Information_Joined[Order Status], "Completed") -> 473.85 | X10: {=_xlfn.ANCHORARRAY($W10)/_xlfn.ANCHORARRAY($V10)} -> 0.2715644 | Y10: {=COUNTIFS(_2_sales_transactions[SKU], 'Competitive Analysis (Step 1)'!$A10:$A209, _2_sales_transactions[Order Status], "Completed")} -> 10 | Z10: {=AVERAGEIFS(_2_sales_transactions[Discount (%)], _2_sales_transactions[SKU], 'Competitive Analysis (Step 1)'!$A10:$A209, _2_sales_transactions[Order Status], "Completed")} -> 5 | AA10: {=COUNTIFS(Transactions_and_Customer_Information_Joined[SKU], 'Competitive Analysis (Step 1)'!$A10:$A209, Transactions_and_Customer_Information_Joined[Order Status], "Completed", Transactions_and_Customer_Information_Joined[3_customer_segments.Discount Sensitivity], "High") /_xlfn.ANCHORARRAY($Y10)} -> 0.3 | AB10: {=COUNTIFS(Transactions_and_Customer_Information_Joined[SKU], 'Competitive Analysis (Step 1)'!$A10:$A209, Transactions_and_Customer_Information_Joined[3_customer_segments.Segment], "Loyal High-Value", Transactions_and_Customer_Information_Joined[Order Status], "Completed") /_xlfn.ANCHORARRAY($Y10)} -> 0.1 | AC10: {=COUNTIFS(Transactions_and_Customer_Information_Joined[SKU], 'Competitive Analysis (Step 1)'!$A10:$A209, Transactions_and_Customer_Information_Joined[3_customer_segments.Segment], "At-Risk Churner", Transactions_and_Customer_Information_Joined[Order Status], "Completed") /_xlfn.ANCHORARRAY($Y10)} -> 0.1 | AD10: {=COUNTIFS(Transactions_and_Customer_Information_Joined[SKU], 'Competitive Analysis (Step 1)'!$A10:$A209, Transactions_and_Customer_Information_Joined[3_customer_segments.Segment], "Dormant", Transactions_and_Customer_Information_Joined[Order Status], "Completed") /_xlfn.ANCHORARRAY($Y10)} -> 0.3 | AE10: {=COUNTIFS(Transactions_and_Customer_Information_Joined[SKU], 'Competitive Analysis (Step 1)'!$A10:$A209, Transactions_and_Customer_Information_Joined[3_customer_segments.Segment], "Deal Hunter", Transactions_and_Customer_Information_Joined[Order Status], "Completed") /_xlfn.ANCHORARRAY($Y10)} -> 0.1 | AF10: {=AVERAGEIFS(Transactions_and_Customer_Information_Joined[3_customer_segments.Days Since Last Order], Transactions_and_Customer_Information_Joined[Order Status], "Completed", Transactions_and_Customer_Information_Joined[SKU], 'Competitive Analysis (Step 1)'!$A10:$A209)} -> 165.5 | AG10: {=COUNTIFS(Transactions_and_Customer_Information_Joined[SKU], 'Competitive Analysis (Step 1)'!$A10:$A209, Transactions_and_Customer_Information_Joined[Order Status], "Returned") / ('Competitive Analysis (Step 1)'!$Y10 + COUNTIFS(Transactions_and_Customer_Information_Joined[SKU], 'Competitive Analysis (Step 1)'!$A10:$A209, Transactions_and_Customer_Information_Joined[Order Status], "Returned"))} -> 0.33333333 | AH10: {=COUNTIFS(Transactions_and_Customer_Information_Joined[SKU], 'Competitive Analysis (Step 1)'!$A10:$A209, Transactions_and_Customer_Information_Joined[Order Status], "Cancelled") / ('Competitive Analysis (Step 1)'!$Y10 + COUNTIFS(Transactions_and_Customer_Information_Joined[SKU], 'Competitive Analysis (Step 1)'!$A10:$A209, Transactions_and_Customer_Information_Joined[Order Status], "Cancelled"))} -> 0.090909091 | AI10: {=_xlfn.IFS($I10:$I209 >$B$2, "Reduce", $I10:$I209 < - $B$2, "Raise", OR($I10:$I209 > -$B$2, $I10:$I209 < $B$2), "Hold")} -> Reduce
A11: SKU-1000 | B11: Wireless Earbuds | C11: ShopNow | D11: 76.06 | E11: 3.2 | F11: 1664 | G11: 45314 | H11: 71.835 | I11: =($K11 - $D11) / $D11 -> 0.0061793321 | J11: Electronics | K11: 76.53 | L11: 52.96 | M11: 0.3079838 | N11: 4.5 | O11: 2781 | P11: 71 | Q11: 24 | R11: 1836.72 | S11: 1271.04 | T11: 565.68 | U11: 91.83 | V11: 1744.89 | W11: =SUMIFS(Transactions_and_Customer_Information_Joined[Gross Profit ($)], Transactions_and_Customer_Information_Joined[SKU], 'Competitive Analysis (Step 1)'!$A11, Transactions_and_Customer_Information_Joined[Order Status], "Completed") -> 473.85 | X11: 0.2715644 | Y11: 10 | Z11: 5 | AA11: 0.3 | AB11: 0.1 | AC11: 0.1 | AD11: 0.3 | AE11: 0.1 | AF11: 165.5 | AG11: 0.33333333 | AH11: 0.090909091 | AI11: Hold
A12: SKU-1000 | B12: Wireless Earbuds | C12: BestDeals | D12: 76.63 | E12: 3 | F12: 479 | G12: 45347 | H12: 71.835 | I12: =($K12 - $D12) / $D12 -> -0.0013049719 | J12: Electronics | K12: 76.53 | L12: 52.96 | M12: 0.3079838 | N12: 4.5 | O12: 2781 | P12: 71 | Q12: 24 | R12: 1836.72 | S12: 1271.04 | T12: 565.68 | U12: 91.83 | V12: 1744.89 | W12: =SUMIFS(Transactions_and_Customer_Information_Joined[Gross Profit ($)], Transactions_and_Customer_Information_Joined[SKU], 'Competitive Analysis (Step 1)'!$A12, Transactions_and_Customer_Information_Joined[Order Status], "Completed") -> 473.85 | X12: 0.2715644 | Y12: 10 | Z12: 5 | AA12: 0.3 | AB12: 0.1 | AC12: 0.1 | AD12: 0.3 | AE12: 0.1 | AF12: 165.5 | AG12: 0.33333333 | AH12: 0.090909091 | AI12: Hold
A13: SKU-1000 | B13: Wireless Earbuds | C13: QuickCart | D13: 71.59 | E13: 4.8 | F13: 1407 | G13: 45368 | H13: 71.835 | I13: =($K13 - $D13) / $D13 -> 0.069004051 | J13: Electronics | K13: 76.53 | L13: 52.96 | M13: 0.3079838 | N13: 4.5 | O13: 2781 | P13: 71 | Q13: 24 | R13: 1836.72 | S13: 1271.04 | T13: 565.68 | U13: 91.83 | V13: 1744.89 | W13: =SUMIFS(Transactions_and_Customer_Information_Joined[Gross Profit ($)], Transactions_and_Customer_Information_Joined[SKU], 'Competitive Analysis (Step 1)'!$A13, Transactions_and_Customer_Information_Joined[Order Status], "Completed") -> 473.85 | X13: 0.2715644 | Y13: 10 | Z13: 5 | AA13: 0.3 | AB13: 0.1 | AC13: 0.1 | AD13: 0.3 | AE13: 0.1 | AF13: 165.5 | AG13: 0.33333333 | AH13: 0.090909091 | AI13: Hold
A14: SKU-1001 | B14: Bluetooth Speaker | C14: RivalMart | D14: 60.11 | E14: 4.9 | F14: 2485 | G14: 45326 | H14: 56.81 | I14: =($K14 - $D14) / $D14 -> -0.11395774 | J14: Electronics | K14: 53.26 | L14: 36.64 | M14: 0.31205407 | N14: 3.4 | O14: 2671 | P14: 287 | Q14: 21 | R14: 1118.46 | S14: 769.44 | T14: 349.02 | U14: 101.2 | V14: 1017.26 | W14: =SUMIFS(Transactions_and_Customer_Information_Joined[Gross Profit ($)], Transactions_and_Customer_Information_Joined[SKU], 'Competitive Analysis (Step 1)'!$A14, Transactions_and_Customer_Information_Joined[Order Status], "Completed") -> 247.82 | X14: 0.46581012 | Y14: 9 | Z14: 8.8888889 | AA14: 0.33333333 | AB14: 0.11111111 | AC14: 0.11111111 | AD14: 0.22222222 | AE14: 0.11111111 | AF14: 214.22222 | AG14: 0.16666667 | AH14: 0.33333333 | AI14: Raise
A15: SKU-1001 | B15: Bluetooth Speaker | C15: ShopNow | D15: 64.58 | E15: 3.7 | F15: 2332 | G15: 45358 | H15: 56.81 | I15: =($K15 - $D15) / $D15 -> -0.17528647 | J15: Electronics | K15: 53.26 | L15: 36.64 | M15: 0.31205407 | N15: 3.4 | O15: 2671 | P15: 287 | Q15: 21 | R15: 1118.46 | S15: 769.44 | T15: 349.02 | U15: 101.2 | V15: 1017.26 | W15: =SUMIFS(Transactions_and_Customer_Information_Joined[Gross Profit ($)], Transactions_and_Customer_Information_Joined[SKU], 'Competitive Analysis (Step 1)'!$A15, Transactions_and_Customer_Information_Joined[Order Status], "Completed") -> 247.82 | X15: 0.46581012 | Y15: 9 | Z15: 8.8888889 | AA15: 0.33333333 | AB15: 0.11111111 | AC15: 0.11111111 | AD15: 0.22222222 | AE15: 0.11111111 | AF15: 214.22222 | AG15: 0.16666667 | AH15: 0.33333333 | AI15: Raise
A16: SKU-1001 | B16: Bluetooth Speaker | C16: BestDeals | D16: 56.33 | E16: 4.1 | F16: 2209 | G16: 45344 | H16: 56.81 | I16: =($K16 - $D16) / $D16 -> -0.054500266 | J16: Electronics | K16: 53.26 | L16: 36.64 | M16: 0.31205407 | N16: 3.4 | O16: 2671 | P16: 287 | Q16: 21 | R16: 1118.46 | S16: 769.44 | T16: 349.02 | U16: 101.2 | V16: 1017.26 | W16: =SUMIFS(Transactions_and_Customer_Information_Joined[Gross Profit ($)], Transactions_and_Customer_Information_Joined[SKU], 'Competitive Analysis (Step 1)'!$A16, Transactions_and_Customer_Information_Joined[Order Status], "Completed") -> 247.82 | X16: 0.46581012 | Y16: 9 | Z16: 8.8888889 | AA16: 0.33333333 | AB16: 0.11111111 | AC16: 0.11111111 | AD16: 0.22222222 | AE16: 0.11111111 | AF16: 214.22222 | AG16: 0.16666667 | AH16: 0.33333333 | AI16: Hold
A17: SKU-1001 | B17: Bluetooth Speaker | C17: QuickCart | D17: 46.22 | E17: 4.1 | F17: 1896 | G17: 45382 | H17: 56.81 | I17: =($K17 - $D17) / $D17 -> 0.15231502 | J17: Electronics | K17: 53.26 | L17: 36.64 | M17: 0.31205407 | N17: 3.4 | O17: 2671 | P17: 287 | Q17: 21 | R17: 1118.46 | S17: 769.44 | T17: 349.02 | U17: 101.2 | V17: 1017.26 | W17: =SUMIFS(Transactions_and_Customer_Information_Joined[Gross Profit ($)], Transactions_and_Customer_Information_Joined[SKU], 'Competitive Analysis (Step 1)'!$A17, Transactions_and_Customer_Information_Joined[Order Status], "Completed") -> 247.82 | X17: 0.46581012 | Y17: 9 | Z17: 8.8888889 | AA17: 0.33333333 | AB17: 0.11111111 | AC17: 0.11111111 | AD17: 0.22222222 | AE17: 0.11111111 | AF17: 214.22222 | AG17: 0.16666667 | AH17: 0.33333333 | AI17: Reduce
A18: SKU-1002 | B18: Smart Watch | C18: RivalMart | D18: 60.69 | E18: 3.5 | F18: 1138 | G18: 45307 | H18: 63.75 | I18: =($K18 - $D18) / $D18 -> 0.21173175 | J18: Electronics | K18: 73.54 | L18: 38.69 | M18: 0.47389176 | N18: 3.8 | O18: 1148 | P18: 357 | Q18: 35 | R18: 2290.05 | S18: 1354.15 | T18: 935.9 | U18: 137.41 | V18: 2152.64 | W18: =SUMIFS(Transactions_and_Customer_Information_Joined[Gross Profit ($)], Transactions_and_Customer_Information_Joined[SKU], 'Competitive Analysis (Step 1)'!$A18, Transactions_and_Customer_Information_Joined[Order Status], "Completed") -> 798.49 | X18: 0.22012506 | Y18: 15 | Z18: 5.6666667 | AA18: 0.53333333 | AB18: 0.33333333 | AC18: 0.2 | AD18: 0.066666667 | AE18: 0.066666667 | AF18: 183.33333 | AG18: 0.23076923 | AH18: 0.52380952 | AI18: Reduce
A19: SKU-1002 | B19: Smart Watch | C19: ShopNow | D19: 71.58 | E19: 4.3 | F19: 1230 | G19: 45320 | H19: 63.75 | I19: =($K19 - $D19) / $D19 -> 0.02738195 | J19: Electronics | K19: 73.54 | L19: 38.69 | M19: 0.47389176 | N19: 3.8 | O19: 1148 | P19: 357 | Q19: 35 | R19: 2290.05 | S19: 1354.15 | T19: 935.9 | U19: 137.41 | V19: 2152.64 | W19: =SUMIFS(Transactions_and_Customer_Information_Joined[Gross Profit ($)], Transactions_and_Customer_Information_Joined[SKU], 'Competitive Analysis (Step 1)'!$A19, Transactions_and_Customer_Information_Joined[Order Status], "Completed") -> 798.49 | X19: 0.22012506 | Y19: 15 | Z19: 5.6666667 | AA19: 0.53333333 | AB19: 0.33333333 | AC19: 0.2 | AD19: 0.066666667 | AE19: 0.066666667 | AF19: 183.33333 | AG19: 0.23076923 | AH19: 0.52380952 | AI19: Hold
A20: SKU-1002 | B20: Smart Watch | C20: BestDeals | D20: 58.29 | E20: 3.4 | F20: 296 | G20: 45337 | H20: 63.75 | I20: =($K20 - $D20) / $D20 -> 0.26162292 | J20: Electronics | K20: 73.54 | L20: 38.69 | M20: 0.47389176 | N20: 3.8 | O20: 1148 | P20: 357 | Q20: 35 | R20: 2290.05 | S20: 1354.15 | T20: 935.9 | U20: 137.41 | V20: 2152.64 | W20: =SUMIFS(Transactions_and_Customer_Information_Joined[Gross Profit ($)], Transactions_and_Customer_Information_Joined[SKU], 'Competitive Analysis (Step 1)'!$A20, Transactions_and_Customer_Information_Joined[Order Status], "Completed") -> 798.49 | X20: 0.22012506 | Y20: 15 | Z20: 5.6666667 | AA20: 0.53333333 | AB20: 0.33333333 | AC20: 0.2 | AD20: 0.066666667 | AE20: 0.066666667 | AF20: 183.33333 | AG20: 0.23076923 | AH20: 0.52380952 | AI20: Reduce
A21: SKU-1002 | B21: Smart Watch | C21: QuickCart | D21: 64.44 | E21: 4 | F21: 1899 | G21: 45341 | H21: 63.75 | I21: =($K21 - $D21) / $D21 -> 0.14121664 | J21: Electronics | K21: 73.54 | L21: 38.69 | M21: 0.47389176 | N21: 3.8 | O21: 1148 | P21: 357 | Q21: 35 | R21: 2290.05 | S21: 1354.15 | T21: 935.9 | U21: 137.41 | V21: 2152.64 | W21: =SUMIFS(Transactions_and_Customer_Information_Joined[Gross Profit ($)], Transactions_and_Customer_Information_Joined[SKU], 'Competitive Analysis (Step 1)'!$A21, Transactions_and_Customer_Information_Joined[Order Status], "Completed") -> 798.49 | X21: 0.22012506 | Y21: 15 | Z21: 5.6666667 | AA21: 0.53333333 | AB21: 0.33333333 | AC21: 0.2 | AD21: 0.066666667 | AE21: 0.066666667 | AF21: 183.33333 | AG21: 0.23076923 | AH21: 0.52380952 | AI21: Reduce
A22: SKU-1003 | B22: Portable Charger | C22: RivalMart | D22: 126.85 | E22: 4 | F22: 1482 | G22: 45355 | H22: 141.6025 | I22: =($K22 - $D22) / $D22 -> 0.21426882 | J22: Electronics | K22: 154.03 | L22: 76.79 | M22: 0.50146075 | N22: 4.7 | O22: 2482 | P22: 183 | Q22: 23 | R22: 3542.69 | S22: 1766.17 | T22: 1776.52 | U22: 269.55 | V22: 3273.14 | W22: =SUMIFS(Transactions_and_Customer_Information_Joined[Gross Profit ($)], Transactions_and_Customer_Information_Joined[SKU], 'Competitive Analysis (Step 1)'!$A22, Transactions_and_Customer_Information_Joined[Order Status], "Completed") -> 1506.97 | X22: 0.14476924 | Y22: 10 | Z22: 7 | AA22: 0.5 | AB22: 0 | AC22: 0.1 | AD22: 0.3 | AE22: 0.2 | AF22: 140.4 | AG22: 0.28571429 | AH22: 0.41176471 | AI22: Reduce
... A209: SKU-1049 | B209: Protein Shaker | C209: QuickCart | D209: 102.76 | E209: 3.1 | F209: 13 | G209: 45344 | H209: 107.1925 | I209: =($K209 - $D209) / $D209 -> -0.029291553 | J209: Sports & Outdoors | K209: 99.75 | L209: 38.13 | M209: 0.61774436 | N209: 3.2 | O209: 2121 | P209: 337 | Q209: 34 | R209: 3047.08 | S209: 1296.42 | T209: 1750.66 | U209: 295.75 | V209: 2751.33 | W209: =SUMIFS(Transactions_and_Customer_Information_Joined[Gross Profit ($)], Transactions_and_Customer_Information_Joined[SKU], 'Competitive Analysis (Step 1)'!$A209, Transactions_and_Customer_Information_Joined[Order Status], "Completed") -> 1454.91 | X209: 0.1722258 | Y209: 13 | Z209: 9.6153846 | AA209: 0.23076923 | AB209: 0.15384615 | AC209: 0.15384615 | AD209: 0.076923077 | AE209: 0.076923077 | AF209: 122.53846 | AG209: 0.23076923 | AH209: 0.33333333 | AI209: Hold

Sheet V1 Pricing Model (Step 2)
A1: PRICING MODEL ASSUMPTIONS | B1: Values
A2: Analysis Reference Date (Assumed) | B2: 45382
A3: Tolerance Band | B3: 0.08
A4: Tie-Break Rule | B4: Raise
A5: Raise Premium | B5: 0.05
A6: Rating Price Adjustment | B6: 0.03
A7: Reduce - Weak | B7: 0.95
A8: Rating Threshold for Reduce - Weak | B8: -0.3
A9: Reduce - Neutral | B9: 0.98
A10: Hold - Strong rating nudge | B10: 1.01
A11: Rating Threshold for Hold - Strong | B11: 0.3
A12: Raise Elasticity | B12: -0.4
A13: Reduce Elasticity | B13: -0.8
A14: Margin Floor | B14: 0.2
A15: Hold - Max Price Movement | B15: 0.08
A16: Signal Score Threshold | B16: 0.05
... A19: Inventory Sensitivity | B19: -0.02
A21: SKU | B21: Product Name | C21: Category | D21: Our Price (Retail) | E21: Our COGS | F21: Stock Units | G21: Average Monthly Volume | H21: Stock Ratio | I21: Gross Margin % | J21: Avg Competitor Price | K21: Price Gap $ | L21: Price Gap % | M21: Our Rating | N21: Avg Competitor Rating | O21: Rating Delta | P21: Category Median Margin | Q21: Inventory Modifier | R21: Weighted Signal Score | S21: Recommendation | T21: Tie Breaker Recommendation | U21: Suggested Price | V21: Difference from Current $ | W21: Difference from Current % | X21: Difference from Avg Competitor $ | Y21: Difference from Average Competitor % | Z21: Volume Change % | AA21: New Volume | AB21: Projected Gross Revenue | AC21: Gross Revenue Impact | AD21: Projected Gross Revenue Lift | AE21: Projected COGS | AF21: Projected COGS Impact | AG21: Projected COGS Lift | AH21: Projected Gross Profit | AI21: Projected Gross Profit Impact | AJ21: Projected Gross Profit Margin % | AK21: Projected Gross Profit Margin Lift | AL21: Final Candidate for Churn Input
A22: {=_xlfn.UNIQUE(_1_product_catalog_pricing[SKU])} -> SKU-1000 | B22: {=_xlfn.XLOOKUP(_xlfn.ANCHORARRAY($A22), 'Competitive Analysis (Step 1)'!$A10:$A209, 'Competitive Analysis (Step 1)'!$B10:$B209, ,0)} -> Wireless Earbuds | C22: {=_xlfn.XLOOKUP(_xlfn.ANCHORARRAY($A22), 'Competitive Analysis (Step 1)'!$A10:$A209,_xlfn.ANCHORARRAY( 'Competitive Analysis (Step 1)'!J10),,0)} -> Electronics | D22: {=_xlfn.XLOOKUP(_xlfn.ANCHORARRAY($A22), 'Competitive Analysis (Step 1)'!$A10:$A209,_xlfn.ANCHORARRAY( 'Competitive Analysis (Step 1)'!$K10))} -> 76.53 | E22: {=_xlfn.XLOOKUP(_xlfn.ANCHORARRAY($A22), 'Competitive Analysis (Step 1)'!$A10:$A209,_xlfn.ANCHORARRAY( 'Competitive Analysis (Step 1)'!$L10),,0)} -> 52.96 | F22: {=_xlfn.XLOOKUP($A22,'Competitive Analysis (Step 1)'!$A$10:$A$209,_xlfn.ANCHORARRAY( 'Competitive Analysis (Step 1)'!$P$10),,0)} -> 71 | G22: {=SUMPRODUCT((Transactions_and_Customer_Information_Joined[SKU]='V1 Pricing Model (Step 2)'!$A22) * (Transactions_and_Customer_Information_Joined[Order Status]="Completed") * (Transactions_and_Customer_Information_Joined[Quantity])) / 12} -> 2 | H22: =IF($G22=0, 99, $F22/$G22) -> 35.5 | I22: =($D22-$E22)/$D22 -> 0.3079838 | J22: {=(SMALL(IF('Competitive Analysis (Step 1)'!$A$10:$A$209=$A22,'Competitive Analysis (Step 1)'!$D$10:$D$209),2)+SMALL(IF('Competitive Analysis (Step 1)'!$A$10:$A$209=$A22,'Competitive Analysis (Step 1)'!$D$10:$D$209),3))/2} -> 73.825 | K22: =$J22-$D22 -> -2.705 | L22: =$K22/$D22 -> -0.035345616 | M22: {=_xlfn.XLOOKUP(_xlfn.ANCHORARRAY($A22), 'Competitive Analysis (Step 1)'!$A10:$A209,_xlfn.ANCHORARRAY( 'Competitive Analysis (Step 1)'!$N10))} -> 4.5 | N22: {=AVERAGEIF('Competitive Analysis (Step 1)'!$A10:$A209,_xlfn.ANCHORARRAY( 'V1 Pricing Model (Step 2)'!$A22), 'Competitive Analysis (Step 1)'!$E10:$E209)} -> 3.825 | O22: {=_xlfn.ANCHORARRAY($M22) -_xlfn.ANCHORARRAY($N22)} -> 0.675 | P22: {=MEDIAN(IF($C$22:$C$71=$C22, $I$22:$I$71))} -> 0.5261518 | Q22: {=_xlfn.LET( _xlpm.stock, $F22, _xlpm.stock_ratio, $H22, _xlpm.cat_ratios, IF($C$22:$C$71=$C22, $H$22:$H$71), _xlpm.cat_median, MEDIAN(_xlpm.cat_ratios), _xlpm.cat_stdev, STDEV(IF($C$22:$C$71=$C22, $H$22:$H$71)), _xlpm.z_score, IF(_xlpm.cat_stdev = 0, 0, (_xlpm.stock_ratio - _xlpm.cat_median) / _xlpm.cat_stdev), _xlpm.capped_z, MIN(MAX(_xlpm.z_score, -2), 2), IF(_xlpm.stock < $B$18, 0, 1 + $B$19 * _xlpm.capped_z) )} -> 1.0201885 | R22: {=_xlfn.LET( _xlpm.sku, $A22, _xlpm.tol, $B$3, _xlpm.sku_range, 'Competitive Analysis (Step 1)'!$A$10:$A$209, _xlpm.comp_prices, 'Competitive Analysis (Step 1)'!$D$10:$D$209, _xlpm.comp_reviews, 'Competitive Analysis (Step 1)'!$F$10:$F$209, _xlpm.obs_dates, 'Competitive Analysis (Step 1)'!$G$10:$G$209, _xlpm.our_price, $D22, _xlpm.matches, (_xlpm.sku_range=_xlpm.sku), _xlpm.deltas, IF(_xlpm.matches, (_xlpm.our_price - _xlpm.comp_prices) / _xlpm.comp_prices, 0), _xlpm.review_wt, IF(_xlpm.matches, LN(_xlpm.comp_reviews + 1), 0), _xlpm.decay_wt, IFERROR(IF(_xlpm.matches, EXP(-$B$17 * ($B$2 - _xlpm.obs_dates)), 0), 0), _xlpm.weights, _xlpm.review_wt * _xlpm.decay_wt, _xlpm.outside_band, IF(ABS(_xlpm.deltas) > _xlpm.tol, 1, 0), _xlpm.total_weight, SUMPRODUCT(_xlpm.weights * _xlpm.matches), _xlpm.weighted_signal, SUMPRODUCT(_xlpm.weights * _xlpm.deltas * _xlpm.outside_band), IF(_xlpm.total_weight = 0, 0, _xlpm.weighted_signal / _xlpm.total_weight) )} -> 0.03532219 | S22: =IF($R22 < -$B$16, "Raise", IF($R22 > $B$16, "Reduce", "Hold")) -> Hold | T22: {=IF($S22="Hold", IF(0.5 * ($P22-$I22) / $P22 + 0.5 * ($R22 / MAX(ABS($R22:$R71))) > 0, "Raise", "Hold"), $S22)} -> Raise | U22: =IF($Q22=0, $D22, _xlfn.LET( _xlpm.raw_price, $Q22 * IF($T22="Raise", ($J22*(1+$B$5)) + ($J22 * MIN($B$6*ABS($O22), $B$5) * SIGN($O22)), IF($T22="Reduce", $J22 * ($B$7 + ($B$9-$B$7) / (1+EXP(-20*($O22-$B$8)))), IF($T22="Hold", IF($O22>$B$11, MIN(MAX($D22, ($J22*$B$10)+($J22 * MIN($B$6*ABS($O22), $B$5) * SIGN($O22))), $D22*(1+$B$15)), $D22)))), IF(AND(OR($T22="Hold", $T22="Reduce"), _xlpm.raw_price < $D22, _xlpm.raw_price >= $D22 * 0.95), $D22, _xlpm.raw_price) )) -> 80.606323 | V22: =$U22-$D22 -> 4.0763228 | W22: =$V22/$D22 -> 0.053264378 | X22: =$U22-$J22 -> 6.7813228 | Y22: =$X22/$J22 -> 0.091856727 | Z22: =IF($V22 = 0, 0, IF($S22="Reduce", $W22*$B$13, $W22*$B$12)) -> -0.021305751 | AA22: {=ROUND(_xlfn.XLOOKUP($A22, 'Competitive Analysis (Step 1)'!$A$10:$A$209,_xlfn.ANCHORARRAY( 'Competitive Analysis (Step 1)'!$Q$10), , 0) * (1+$Z22), 0)} -> 23 | AB22: =$AA22*$U22 -> 1853.9454 | AC22: {=$AB22 - _xlfn.XLOOKUP($A22, 'Competitive Analysis (Step 1)'!$A$10:$A$209,_xlfn.ANCHORARRAY( 'Competitive Analysis (Step 1)'!$R$10), ,0)} -> 17.225425 | AD22: {=$AC22 / _xlfn.XLOOKUP($A22, 'Competitive Analysis (Step 1)'!$A$10:$A$209,_xlfn.ANCHORARRAY( 'Competitive Analysis (Step 1)'!$V$10), ,0)} -> 0.0098719262 | AE22: =$AA22 * _xlfn.XLOOKUP($A22, _1_product_catalog_pricing[SKU], _1_product_catalog_pricing[Cost Price ($)], , 0) -> 1218.08 | AF22: {=$AE22 - _xlfn.XLOOKUP($A22, 'Competitive Analysis (Step 1)'!$A$10:$A$209,_xlfn.ANCHORARRAY( 'Competitive Analysis (Step 1)'!$S$10),,0)} -> -52.96 | AG22: {=$AF22 / _xlfn.XLOOKUP($A22, 'Competitive Analysis (Step 1)'!$A$10:$A$209,_xlfn.ANCHORARRAY( 'Competitive Analysis (Step 1)'!$S$10),,0)} -> -0.041666667 | AH22: =$AB22-$AE22 -> 635.86543 | AI22: {=$AH22 - _xlfn.XLOOKUP($A22, 'Competitive Analysis (Step 1)'!$A$10:$A$209,_xlfn.ANCHORARRAY( 'Competitive Analysis (Step 1)'!$T$10),,0)} -> 70.185425 | AJ22: =IFERROR($AH22 / $AB22, 0) -> 0.34297958 | AK22: {=$AI22 / _xlfn.XLOOKUP($A22, 'Competitive Analysis (Step 1)'!$A$10:$A$209,_xlfn.ANCHORARRAY( 'Competitive Analysis (Step 1)'!$T$10),,0)} -> 0.12407267 | AL22: =IF($AK22 > 0, "Full", IF($AK22 >= $B$20, "Constrained", "Exclude")) -> Full
A23: SKU-1001 | B23: Bluetooth Speaker | C23: Electronics | D23: 53.26 | E23: 36.64 | F23: {=_xlfn.XLOOKUP($A23,'Competitive Analysis (Step 1)'!$A$10:$A$209,_xlfn.ANCHORARRAY( 'Competitive Analysis (Step 1)'!$P$10),,0)} -> 287 | G23: {=SUMPRODUCT((Transactions_and_Customer_Information_Joined[SKU]='V1 Pricing Model (Step 2)'!$A23) * (Transactions_and_Customer_Information_Joined[Order Status]="Completed") * (Transactions_and_Customer_Information_Joined[Quantity])) / 12} -> 1.75 | H23: =IF($G23=0, 99, $F23/$G23) -> 164 | I23: =($D23-$E23)/$D23 -> 0.31205407 | J23: {=(SMALL(IF('Competitive Analysis (Step 1)'!$A$10:$A$209=$A23,'Competitive Analysis (Step 1)'!$D$10:$D$209),2)+SMALL(IF('Competitive Analysis (Step 1)'!$A$10:$A$209=$A23,'Competitive Analysis (Step 1)'!$D$10:$D$209),3))/2} -> 58.22 | K23: =$J23-$D23 -> 4.96 | L23: =$K23/$D23 -> 0.093128051 | M23: 3.4 | N23: 4.2 | O23: -0.8 | P23: {=MEDIAN(IF($C$22:$C$71=$C23, $I$22:$I$71))} -> 0.5261518 | Q23: {=_xlfn.LET( _xlpm.stock, $F23, _xlpm.stock_ratio, $H23, _xlpm.cat_ratios, IF($C$22:$C$71=$C23, $H$22:$H$71), _xlpm.cat_median, MEDIAN(_xlpm.cat_ratios), _xlpm.cat_stdev, STDEV(IF($C$22:$C$71=$C23, $H$22:$H$71)), _xlpm.z_score, IF(_xlpm.cat_stdev = 0, 0, (_xlpm.stock_ratio - _xlpm.cat_median) / _xlpm.cat_stdev), _xlpm.capped_z, MIN(MAX(_xlpm.z_score, -2), 2), IF(_xlpm.stock < $B$18, 0, 1 + $B$19 * _xlpm.capped_z) )} -> 0.96367666 | R23: {=_xlfn.LET( _xlpm.sku, $A23, _xlpm.tol, $B$3, _xlpm.sku_range, 'Competitive Analysis (Step 1)'!$A$10:$A$209, _xlpm.comp_prices, 'Competitive Analysis (Step 1)'!$D$10:$D$209, _xlpm.comp_reviews, 'Competitive Analysis (Step 1)'!$F$10:$F$209, _xlpm.obs_dates, 'Competitive Analysis (Step 1)'!$G$10:$G$209, _xlpm.our_price, $D23, _xlpm.matches, (_xlpm.sku_range=_xlpm.sku), _xlpm.deltas, IF(_xlpm.matches, (_xlpm.our_price - _xlpm.comp_prices) / _xlpm.comp_prices, 0), _xlpm.review_wt, IF(_xlpm.matches, LN(_xlpm.comp_reviews + 1), 0), _xlpm.decay_wt, IFERROR(IF(_xlpm.matches, EXP(-$B$17 * ($B$2 - _xlpm.obs_dates)), 0), 0), _xlpm.weights, _xlpm.review_wt * _xlpm.decay_wt, _xlpm.outside_band, IF(ABS(_xlpm.deltas) > _xlpm.tol, 1, 0), _xlpm.total_weight, SUMPRODUCT(_xlpm.weights * _xlpm.matches), _xlpm.weighted_signal, SUMPRODUCT(_xlpm.weights * _xlpm.deltas * _xlpm.outside_band), IF(_xlpm.total_weight = 0, 0, _xlpm.weighted_signal / _xlpm.total_weight) )} -> 0.00096443417 | S23: =IF($R23 < -$B$16, "Raise", IF($R23 > $B$16, "Reduce", "Hold")) -> Hold | T23: {=IF($S23="Hold", IF(0.5 * ($P23-$I23) / $P23 + 0.5 * ($R23 / MAX(ABS($R23:$R72))) > 0, "Raise", "Hold"), $S23)} -> Raise | U23: =IF($Q23=0, $D23, _xlfn.LET( _xlpm.raw_price, $Q23 * IF($T23="Raise", ($J23*(1+$B$5)) + ($J23 * MIN($B$6*ABS($O23), $B$5) * SIGN($O23)), IF($T23="Reduce", $J23 * ($B$7 + ($B$9-$B$7) / (1+EXP(-20*($O23-$B$8)))), IF($T23="Hold", IF($O23>$B$11, MIN(MAX($D23, ($J23*$B$10)+($J23 * MIN($B$6*ABS($O23), $B$5) * SIGN($O23))), $D23*(1+$B$15)), $D23)))), IF(AND(OR($T23="Hold", $T23="Reduce"), _xlpm.raw_price < $D23, _xlpm.raw_price >= $D23 * 0.95), $D23, _xlpm.raw_price) )) -> 57.563992 | V23: =$U23-$D23 -> 4.3039918 | W23: =$V23/$D23 -> 0.080810961 | X23: =$U23-$J23 -> -0.65600821 | Y23: =$X23/$J23 -> -0.011267747 | Z23: =IF($V23 = 0, 0, IF($S23="Reduce", $W23*$B$13, $W23*$B$12)) -> -0.032324384 | AA23: {=ROUND(_xlfn.XLOOKUP($A23, 'Competitive Analysis (Step 1)'!$A$10:$A$209,_xlfn.ANCHORARRAY( 'Competitive Analysis (Step 1)'!$Q$10), , 0) * (1+$Z23), 0)} -> 20 | AB23: =$AA23*$U23 -> 1151.2798 | AC23: {=$AB23 - _xlfn.XLOOKUP($A23, 'Competitive Analysis (Step 1)'!$A$10:$A$209,_xlfn.ANCHORARRAY( 'Competitive Analysis (Step 1)'!$R$10), ,0)} -> 32.819836 | AD23: {=$AC23 / _xlfn.XLOOKUP($A23, 'Competitive Analysis (Step 1)'!$A$10:$A$209,_xlfn.ANCHORARRAY( 'Competitive Analysis (Step 1)'!$V$10), ,0)} -> 0.032262977 | AE23: =$AA23 * _xlfn.XLOOKUP($A23, _1_product_catalog_pricing[SKU], _1_product_catalog_pricing[Cost Price ($)], , 0) -> 732.8 | AF23: {=$AE23 - _xlfn.XLOOKUP($A23, 'Competitive Analysis (Step 1)'!$A$10:$A$209,_xlfn.ANCHORARRAY( 'Competitive Analysis (Step 1)'!$S$10),,0)} -> -36.64 | AG23: {=$AF23 / _xlfn.XLOOKUP($A23, 'Competitive Analysis (Step 1)'!$A$10:$A$209,_xlfn.ANCHORARRAY( 'Competitive Analysis (Step 1)'!$S$10),,0)} -> -0.047619048 | AH23: =$AB23-$AE23 -> 418.47984 | AI23: {=$AH23 - _xlfn.XLOOKUP($A23, 'Competitive Analysis (Step 1)'!$A$10:$A$209,_xlfn.ANCHORARRAY( 'Competitive Analysis (Step 1)'!$T$10),,0)} -> 69.459836 | AJ23: =IFERROR($AH23 / $AB23, 0) -> 0.36349098 | AK23: {=$AI23 / _xlfn.XLOOKUP($A23, 'Competitive Analysis (Step 1)'!$A$10:$A$209,_xlfn.ANCHORARRAY( 'Competitive Analysis (Step 1)'!$T$10),,0)} -> 0.19901391 | AL23: =IF($AK23 > 0, "Full", IF($AK23 >= $B$20, "Constrained", "Exclude")) -> Full
A24: SKU-1002 | B24: Smart Watch | C24: Electronics | D24: 73.54 | E24: 38.69 | F24: {=_xlfn.XLOOKUP($A24,'Competitive Analysis (Step 1)'!$A$10:$A$209,_xlfn.ANCHORARRAY( 'Competitive Analysis (Step 1)'!$P$10),,0)} -> 357 | G24: {=SUMPRODUCT((Transactions_and_Customer_Information_Joined[SKU]='V1 Pricing Model (Step 2)'!$A24) * (Transactions_and_Customer_Information_Joined[Order Status]="Completed") * (Transactions_and_Customer_Information_Joined[Quantity])) / 12} -> 2.9166667 | H24: =IF($G24=0, 99, $F24/$G24) -> 122.4 | I24: =($D24-$E24)/$D24 -> 0.47389176 | J24: {=(SMALL(IF('Competitive Analysis (Step 1)'!$A$10:$A$209=$A24,'Competitive Analysis (Step 1)'!$D$10:$D$209),2)+SMALL(IF('Competitive Analysis (Step 1)'!$A$10:$A$209=$A24,'Competitive Analysis (Step 1)'!$D$10:$D$209),3))/2} -> 62.565 | K24: =$J24-$D24 -> -10.975 | L24: =$K24/$D24 -> -0.14923851 | M24: 3.8 | N24: 3.8 | O24: 0 | P24: {=MEDIAN(IF($C$22:$C$71=$C24, $I$22:$I$71))} -> 0.5261518 | Q24: {=_xlfn.LET( _xlpm.stock, $F24, _xlpm.stock_ratio, $H24, _xlpm.cat_ratios, IF($C$22:$C$71=$C24, $H$22:$H$71), _xlpm.cat_median, MEDIAN(_xlpm.cat_ratios), _xlpm.cat_stdev, STDEV(IF($C$22:$C$71=$C24, $H$22:$H$71)), _xlpm.z_score, IF(_xlpm.cat_stdev = 0, 0, (_xlpm.stock_ratio - _xlpm.cat_median) / _xlpm.cat_stdev), _xlpm.capped_z, MIN(MAX(_xlpm.z_score, -2), 2), IF(_xlpm.stock < $B$18, 0, 1 + $B$19 * _xlpm.capped_z) )} -> 0.98197154 | R24: {=_xlfn.LET( _xlpm.sku, $A24, _xlpm.tol, $B$3, _xlpm.sku_range, 'Competitive Analysis (Step 1)'!$A$10:$A$209, _xlpm.comp_prices, 'Competitive Analysis (Step 1)'!$D$10:$D$209, _xlpm.comp_reviews, 'Competitive Analysis (Step 1)'!$F$10:$F$209, _xlpm.obs_dates, 'Competitive Analysis (Step 1)'!$G$10:$G$209, _xlpm.our_price, $D24, _xlpm.matches, (_xlpm.sku_range=_xlpm.sku), _xlpm.deltas, IF(_xlpm.matches, (_xlpm.our_price - _xlpm.comp_prices) / _xlpm.comp_prices, 0), _xlpm.review_wt, IF(_xlpm.matches, LN(_xlpm.comp_reviews + 1), 0), _xlpm.decay_wt, IFERROR(IF(_xlpm.matches, EXP(-$B$17 * ($B$2 - _xlpm.obs_dates)), 0), 0), _xlpm.weights, _xlpm.review_wt * _xlpm.decay_wt, _xlpm.outside_band, IF(ABS(_xlpm.deltas) > _xlpm.tol, 1, 0), _xlpm.total_weight, SUMPRODUCT(_xlpm.weights * _xlpm.matches), _xlpm.weighted_signal, SUMPRODUCT(_xlpm.weights * _xlpm.deltas * _xlpm.outside_band), IF(_xlpm.total_weight = 0, 0, _xlpm.weighted_signal / _xlpm.total_weight) )} -> 0.15186217 | S24: =IF($R24 < -$B$16, "Raise", IF($R24 > $B$16, "Reduce", "Hold")) -> Reduce | T24: {=IF($S24="Hold", IF(0.5 * ($P24-$I24) / $P24 + 0.5 * ($R24 / MAX(ABS($R24:$R73))) > 0, "Raise", "Hold"), $S24)} -> Reduce | U24: =IF($Q24=0, $D24, _xlfn.LET( _xlpm.raw_price, $Q24 * IF($T24="Raise", ($J24*(1+$B$5)) + ($J24 * MIN($B$6*ABS($O24), $B$5) * SIGN($O24)), IF($T24="Reduce", $J24 * ($B$7 + ($B$9-$B$7) / (1+EXP(-20*($O24-$B$8)))), IF($T24="Hold", IF($O24>$B$11, MIN(MAX($D24, ($J24*$B$10)+($J24 * MIN($B$6*ABS($O24), $B$5) * SIGN($O24))), $D24*(1+$B$15)), $D24)))), IF(AND(OR($T24="Hold", $T24="Reduce"), _xlpm.raw_price < $D24, _xlpm.raw_price >= $D24 * 0.95), $D24, _xlpm.raw_price) )) -> 60.203751 | V24: =$U24-$D24 -> -13.336249 | W24: =$V24/$D24 -> -0.18134687 | X24: =$U24-$J24 -> -2.361249 | Y24: =$X24/$J24 -> -0.037740733 | Z24: =IF($V24 = 0, 0, IF($S24="Reduce", $W24*$B$13, $W24*$B$12)) -> 0.1450775 | AA24: {=ROUND(_xlfn.XLOOKUP($A24, 'Competitive Analysis (Step 1)'!$A$10:$A$209,_xlfn.ANCHORARRAY( 'Competitive Analysis (Step 1)'!$Q$10), , 0) * (1+$Z24), 0)} -> 40 | AB24: =$AA24*$U24 -> 2408.15 | AC24: {=$AB24 - _xlfn.XLOOKUP($A24, 'Competitive Analysis (Step 1)'!$A$10:$A$209,_xlfn.ANCHORARRAY( 'Competitive Analysis (Step 1)'!$R$10), ,0)} -> 118.10004 | AD24: {=$AC24 / _xlfn.XLOOKUP($A24, 'Competitive Analysis (Step 1)'!$A$10:$A$209,_xlfn.ANCHORARRAY( 'Competitive Analysis (Step 1)'!$V$10), ,0)} -> 0.054862885 | AE24: =$AA24 * _xlfn.XLOOKUP($A24, _1_product_catalog_pricing[SKU], _1_product_catalog_pricing[Cost Price ($)], , 0) -> 1547.6 | AF24: {=$AE24 - _xlfn.XLOOKUP($A24, 'Competitive Analysis (Step 1)'!$A$10:$A$209,_xlfn.ANCHORARRAY( 'Competitive Analysis (Step 1)'!$S$10),,0)} -> 193.45 | AG24: {=$AF24 / _xlfn.XLOOKUP($A24, 'Competitive Analysis (Step 1)'!$A$10:$A$209,_xlfn.ANCHORARRAY( 'Competitive Analysis (Step 1)'!$S$10),,0)} -> 0.14285714 | AH24: =$AB24-$AE24 -> 860.55004 | AI24: {=$AH24 - _xlfn.XLOOKUP($A24, 'Competitive Analysis (Step 1)'!$A$10:$A$209,_xlfn.ANCHORARRAY( 'Competitive Analysis (Step 1)'!$T$10),,0)} -> -75.349959 | AJ24: =IFERROR($AH24 / $AB24, 0) -> 0.35734901 | AK24: {=$AI24 / _xlfn.XLOOKUP($A24, 'Competitive Analysis (Step 1)'!$A$10:$A$209,_xlfn.ANCHORARRAY( 'Competitive Analysis (Step 1)'!$T$10),,0)} -> -0.080510694 | AL24: =IF($AK24 > 0, "Full", IF($AK24 >= $B$20, "Constrained", "Exclude")) -> Exclude
A25: SKU-1003 | B25: Portable Charger | C25: Electronics | D25: 154.03 | E25: 76.79 | F25: {=_xlfn.XLOOKUP($A25,'Competitive Analysis (Step 1)'!$A$10:$A$209,_xlfn.ANCHORARRAY( 'Competitive Analysis (Step 1)'!$P$10),,0)} -> 183 | G25: {=SUMPRODUCT((Transactions_and_Customer_Information_Joined[SKU]='V1 Pricing Model (Step 2)'!$A25) * (Transactions_and_Customer_Information_Joined[Order Status]="Completed") * (Transactions_and_Customer_Information_Joined[Quantity])) / 12} -> 1.9166667 | H25: =IF($G25=0, 99, $F25/$G25) -> 95.478261 | I25: =($D25-$E25)/$D25 -> 0.50146075 | J25: {=(SMALL(IF('Competitive Analysis (Step 1)'!$A$10:$A$209=$A25,'Competitive Analysis (Step 1)'!$D$10:$D$209),2)+SMALL(IF('Competitive Analysis (Step 1)'!$A$10:$A$209=$A25,'Competitive Analysis (Step 1)'!$D$10:$D$209),3))/2} -> 133.345 | K25: =$J25-$D25 -> -20.685 | L25: =$K25/$D25 -> -0.13429202 | M25: 4.7 | N25: 3.9 | O25: 0.8 | P25: {=MEDIAN(IF($C$22:$C$71=$C25, $I$22:$I$71))} -> 0.5261518 | Q25: {=_xlfn.LET( _xlpm.stock, $F25, _xlpm.stock_ratio, $H25, _xlpm.cat_ratios, IF($C$22:$C$71=$C25, $H$22:$H$71), _xlpm.cat_median, MEDIAN(_xlpm.cat_ratios), _xlpm.cat_stdev, STDEV(IF($C$22:$C$71=$C25, $H$22:$H$71)), _xlpm.z_score, IF(_xlpm.cat_stdev = 0, 0, (_xlpm.stock_ratio - _xlpm.cat_median) / _xlpm.cat_stdev), _xlpm.capped_z, MIN(MAX(_xlpm.z_score, -2), 2), IF(_xlpm.stock < $B$18, 0, 1 + $B$19 * _xlpm.capped_z) )} -> 0.9938112 | R25: {=_xlfn.LET( _xlpm.sku, $A25, _xlpm.tol, $B$3, _xlpm.sku_range, 'Competitive Analysis (Step 1)'!$A$10:$A$209, _xlpm.comp_prices, 'Competitive Analysis (Step 1)'!$D$10:$D$209, _xlpm.comp_reviews, 'Competitive Analysis (Step 1)'!$F$10:$F$209, _xlpm.obs_dates, 'Competitive Analysis (Step 1)'!$G$10:$G$209, _xlpm.our_price, $D25, _xlpm.matches, (_xlpm.sku_range=_xlpm.sku), _xlpm.deltas, IF(_xlpm.matches, (_xlpm.our_price - _xlpm.comp_prices) / _xlpm.comp_prices, 0), _xlpm.review_wt, IF(_xlpm.matches, LN(_xlpm.comp_reviews + 1), 0), _xlpm.decay_wt, IFERROR(IF(_xlpm.matches, EXP(-$B$17 * ($B$2 - _xlpm.obs_dates)), 0), 0), _xlpm.weights, _xlpm.review_wt * _xlpm.decay_wt, _xlpm.outside_band, IF(ABS(_xlpm.deltas) > _xlpm.tol, 1, 0), _xlpm.total_weight, SUMPRODUCT(_xlpm.weights * _xlpm.matches), _xlpm.weighted_signal, SUMPRODUCT(_xlpm.weights * _xlpm.deltas * _xlpm.outside_band), IF(_xlpm.total_weight = 0, 0, _xlpm.weighted_signal / _xlpm.total_weight) )} -> 0.14935681 | S25: =IF($R25 < -$B$16, "Raise", IF($R25 > $B$16, "Reduce", "Hold")) -> Reduce | T25: {=IF($S25="Hold", IF(0.5 * ($P25-$I25) / $P25 + 0.5 * ($R25 / MAX(ABS($R25:$R74))) > 0, "Raise", "Hold"), $S25)} -> Reduce | U25: =IF($Q25=0, $D25, _xlfn.LET( _xlpm.raw_price, $Q25 * IF($T25="Raise", ($J25*(1+$B$5)) + ($J25 * MIN($B$6*ABS($O25), $B$5) * SIGN($O25)), IF($T25="Reduce", $J25 * ($B$7 + ($B$9-$B$7) / (1+EXP(-20*($O25-$B$8)))), IF($T25="Hold", IF($O25>$B$11, MIN(MAX($D25, ($J25*$B$10)+($J25 * MIN($B$6*ABS($O25), $B$5) * SIGN($O25))), $D25*(1+$B$15)), $D25)))), IF(AND(OR($T25="Hold", $T25="Reduce"), _xlpm.raw_price < $D25, _xlpm.raw_price >= $D25 * 0.95), $D25, _xlpm.raw_price) )) -> 129.86936 | V25: =$U25-$D25 -> -24.16064 | W25: =$V25/$D25 -> -0.15685672 | X25: =$U25-$J25 -> -3.4756404 | Y25: =$X25/$J25 -> -0.026065023 | Z25: =IF($V25 = 0, 0, IF($S25="Reduce", $W25*$B$13, $W25*$B$12)) -> 0.12548538 | AA25: {=ROUND(_xlfn.XLOOKUP($A25, 'Competitive Analysis (Step 1)'!$A$10:$A$209,_xlfn.ANCHORARRAY( 'Competitive Analysis (Step 1)'!$Q$10), , 0) * (1+$Z25), 0)} -> 26 | AB25: =$AA25*$U25 -> 3376.6033 | AC25: {=$AB25 - _xlfn.XLOOKUP($A25, 'Competitive Analysis (Step 1)'!$A$10:$A$209,_xlfn.ANCHORARRAY( 'Competitive Analysis (Step 1)'!$R$10), ,0)} -> -166.08665 | AD25: {=$AC25 / _xlfn.XLOOKUP($A25, 'Competitive Analysis (Step 1)'!$A$10:$A$209,_xlfn.ANCHORARRAY( 'Competitive Analysis (Step 1)'!$V$10), ,0)} -> -0.0507423 | AE25: =$AA25 * _xlfn.XLOOKUP($A25, _1_product_catalog_pricing[SKU], _1_product_catalog_pricing[Cost Price ($)], , 0) -> 1996.54 | AF25: {=$AE25 - _xlfn.XLOOKUP($A25, 'Competitive Analysis (Step 1)'!$A$10:$A$209,_xlfn.ANCHORARRAY( 'Competitive Analysis (Step 1)'!$S$10),,0)} -> 230.37 | AG25: {=$AF25 / _xlfn.XLOOKUP($A25, 'Competitive Analysis (Step 1)'!$A$10:$A$209,_xlfn.ANCHORARRAY( 'Competitive Analysis (Step 1)'!$S$10),,0)} -> 0.13043478 | AH25: =$AB25-$AE25 -> 1380.0633 | AI25: {=$AH25 - _xlfn.XLOOKUP($A25, 'Competitive Analysis (Step 1)'!$A$10:$A$209,_xlfn.ANCHORARRAY( 'Competitive Analysis (Step 1)'!$T$10),,0)} -> -396.45665 | AJ25: =IFERROR($AH25 / $AB25, 0) -> 0.40871349 | AK25: {=$AI25 / _xlfn.XLOOKUP($A25, 'Competitive Analysis (Step 1)'!$A$10:$A$209,_xlfn.ANCHORARRAY( 'Competitive Analysis (Step 1)'!$T$10),,0)} -> -0.22316476 | AL25: =IF($AK25 > 0, "Full", IF($AK25 >= $B$20, "Constrained", "Exclude")) -> Exclude
